Workbook

Sheet Export Summary
B3: This document was exported from Numbers. Each table was converted to an Excel worksheet. All other objects on each Numbers sheet were placed on separate worksheets. Please be aware that formula calculations may differ in Excel.
B7: Numbers Sheet Name | C7: Numbers Table Name | D7: Excel Worksheet Name
B9: README
C10: Table 1 | D10: README
B11: Ready_84Q_Assessment
C12: Table 1 | D12: Ready_84Q_Assessment
B13: Metric_Scoring_Rules
C14: Table 1 | D14: Metric_Scoring_Rules
B15: Student_Response_Template
C16: Table 1 | D16: Student_Response_Template
B17: Auto_Score_Summary
C18: Table 1 | D18: Auto_Score_Summary
B19: Permutation_AI_Rules
C20: Table 1 | D20: Permutation_AI_Rules
B21: AI_Logic_Payloads
C22: Table 1 | D22: AI_Logic_Payloads
B23: Timing_Bands
C24: Table 1 | D24: Timing_Bands

Sheet README
A1: NeuroPi Grade 8–12 Compact Psychometric Assessment Pack | D1: NeuroPi Compact Assessment Dashboard
A2: Purpose | B2: Ready-to-use 84-question assessment derived from uploaded 500+ question bank: 3 questions per metric/assessment point. | D2: Total Items | E2: {=COUNTA('Ready_84Q_Assessment'!A1:A86)-1} -> 84
A3: For IT Team | B3: Use Ready_84Q_Assessment as the canonical item bank for MVP/adaptive testing. Use Student_Response_Template and Auto_Score_Summary for scoring logic. | D3: Metrics Covered | E3: {=COUNTA('Metric_Scoring_Rules'!A1:A30)-1} -> 28
A4: For AI Team | B4: Use Metric_Scoring_Rules, Permutation_AI_Rules, and AI_Logic_Payloads to set rules and train/validate recommendation algorithms. | D4: Average Score | E4: {=_xlfn.IFERROR(AVERAGE('Auto_Score_Summary'!D1:D30),"")}
A5: Timing Bands | B5: Each question has Low/Moderate/High time thresholds in seconds. High time is a review signal, not a penalty. | D5: High-Time Review Count | E5: {=COUNTIF('Student_Response_Template'!K1:K86,"High")} -> 0
A6: Layers Included | B6: RIASEC, Big Five, Cognitive, Emotional, Learning Style, Motivation, Study Habits, Career Clarity, Validity/Readiness. | D6: Support Needed Metrics | E6: {=COUNTIF('Auto_Score_Summary'!H1:H30,"Support Needed")} -> 0
A7: Scale | B7: Likert items use 1–5. Cognitive MCQs use correct=1 and incorrect=0. Final metric score is normalized to 0–100. | D7: Timing Review Metrics | E7: {=COUNTIF('Auto_Score_Summary'!H1:H30,"Timing Review")} -> 0
A8: Important | B8: This is a developmental guidance assessment, not a diagnostic or deterministic tool.
A9: Generated On | B9: 2026-05-05 07:59 | D9: Layer | E9: Average Score | F9: Band
D10: Additional NeuroPi Indicators | E10: {=_xlfn.IFERROR(_xlfn.AVERAGEIF('Auto_Score_Summary'!A1:A30,A10,'Auto_Score_Summary'!D1:D30),"")} | F10: {=IF(B10="","",IF(B10<40,"Low",IF(B10<70,"Moderate","High")))}
D11: Big Five Personality | E11: {=_xlfn.IFERROR(_xlfn.AVERAGEIF('Auto_Score_Summary'!A1:A30,A11,'Auto_Score_Summary'!D1:D30),"")} | F11: {=IF(B11="","",IF(B11<40,"Low",IF(B11<70,"Moderate","High")))}
D12: Cognitive Ability | E12: {=_xlfn.IFERROR(_xlfn.AVERAGEIF('Auto_Score_Summary'!A1:A30,A12,'Auto_Score_Summary'!D1:D30),"")} | F12: {=IF(B12="","",IF(B12<40,"Low",IF(B12<70,"Moderate","High")))}
D13: Emotional Profile | E13: {=_xlfn.IFERROR(_xlfn.AVERAGEIF('Auto_Score_Summary'!A1:A30,A13,'Auto_Score_Summary'!D1:D30),"")} | F13: {=IF(B13="","",IF(B13<40,"Low",IF(B13<70,"Moderate","High")))}
D14: Learning Style | E14: {=_xlfn.IFERROR(_xlfn.AVERAGEIF('Auto_Score_Summary'!A1:A30,A14,'Auto_Score_Summary'!D1:D30),"")} | F14: {=IF(B14="","",IF(B14<40,"Low",IF(B14<70,"Moderate","High")))}
D15: RIASEC Interest | E15: {=_xlfn.IFERROR(_xlfn.AVERAGEIF('Auto_Score_Summary'!A1:A30,A15,'Auto_Score_Summary'!D1:D30),"")} | F15: {=IF(B15="","",IF(B15<40,"Low",IF(B15<70,"Moderate","High")))}
D16: Validity & Readiness | E16: {=_xlfn.IFERROR(_xlfn.AVERAGEIF('Auto_Score_Summary'!A1:A30,A16,'Auto_Score_Summary'!D1:D30),"")} | F16: {=IF(B16="","",IF(B16<40,"Low",IF(B16<70,"Moderate","High")))}

Sheet Ready_84Q_Assessment
A1: Assessment_QID | B1: Source_QID | C1: Grade_Band | D1: Layer | E1: Metric | F1: Trait_Code | G1: Question_Type | H1: Question | I1: Option_A | J1: Option_B | K1: Option_C | L1: Option_D | M1: Correct_Key | N1: Scale_Or_Scoring | O1: Reverse_Scored | P1: Difficulty | Q1: Time_Low_Max_Sec | R1: Time_Moderate_Max_Sec | S1: Time_High_Review_Above_Sec | T1: Score_Method | U1: Report_Tag | V1: Counselor_Note | W1: AI_Input_Field | X1: Use_In_Adaptive_Test
A2: AQ001 | B2: NPI0001 | C2: 8-12 | D2: RIASEC Interest | E2: Realistic | F2: R | G2: Likert | H2: I enjoy activities involving building or fixing things. | I2: 1 Strongly Disagree/Dislike | J2: 2 Disagree/Dislike | K2: 3 Neutral/Unsure | L2: 4 Agree/Like | N2: 1-5 Likert: 1=Strongly Disagree/Dislike, 5=Strongly Agree/Like | O2: No | P2: Easy | Q2: 0 | R2: 7 | S2: 18 | T2: Likert 1-5 normalized; reverse if flagged | U2: Realistic Interest | V2: Higher response increases interest score. | W2: RIASEC Interest::Realistic::R | X2: Yes
A3: AQ002 | B3: NPI0009 | C3: 8-12 | D3: RIASEC Interest | E3: Realistic | F3: R | G3: Likert | H3: I enjoy activities involving practical experiments. | I3: 1 Strongly Disagree/Dislike | J3: 2 Disagree/Dislike | K3: 3 Neutral/Unsure | L3: 4 Agree/Like | N3: 1-5 Likert: 1=Strongly Disagree/Dislike, 5=Strongly Agree/Like | O3: No | P3: Medium | Q3: 0 | R3: 10 | S3: 25 | T3: Likert 1-5 normalized; reverse if flagged | U3: Realistic Interest | V3: Higher response increases interest score. | W3: RIASEC Interest::Realistic::R | X3: Yes
A4: AQ003 | B4: NPI0002 | C4: 8-12 | D4: RIASEC Interest | E4: Realistic | F4: R | G4: Likert | H4: I enjoy activities involving using tools or equipment. | I4: 1 Strongly Disagree/Dislike | J4: 2 Disagree/Dislike | K4: 3 Neutral/Unsure | L4: 4 Agree/Like | N4: 1-5 Likert: 1=Strongly Disagree/Dislike, 5=Strongly Agree/Like | O4: No | P4: Easy | Q4: 0 | R4: 7 | S4: 18 | T4: Likert 1-5 normalized; reverse if flagged | U4: Realistic Interest | V4: Higher response increases interest score. | W4: RIASEC Interest::Realistic::R | X4: Yes
A5: AQ004 | B5: NPI0016 | C5: 8-12 | D5: RIASEC Interest | E5: Investigative | F5: I | G5: Likert | H5: I enjoy activities involving solving puzzles. | I5: 1 Strongly Disagree/Dislike | J5: 2 Disagree/Dislike | K5: 3 Neutral/Unsure | L5: 4 Agree/Like | N5: 1-5 Likert: 1=Strongly Disagree/Dislike, 5=Strongly Agree/Like | O5: No | P5: Easy | Q5: 0 | R5: 7 | S5: 18 | T5: Likert 1-5 normalized; reverse if flagged | U5: Investigative Interest | V5: Higher response increases interest score. | W5: RIASEC Interest::Investigative::I | X5: Yes
A6: AQ005 | B6: NPI0024 | C6: 8-12 | D6: RIASEC Interest | E6: Investigative | F6: I | G6: Likert | H6: I enjoy activities involving evidence-based decisions. | I6: 1 Strongly Disagree/Dislike | J6: 2 Disagree/Dislike | K6: 3 Neutral/Unsure | L6: 4 Agree/Like | N6: 1-5 Likert: 1=Strongly Disagree/Dislike, 5=Strongly Agree/Like | O6: No | P6: Medium | Q6: 0 | R6: 10 | S6: 25 | T6: Likert 1-5 normalized; reverse if flagged | U6: Investigative Interest | V6: Higher response increases interest score. | W6: RIASEC Interest::Investigative::I | X6: Yes
A7: AQ006 | B7: NPI0017 | C7: 8-12 | D7: RIASEC Interest | E7: Investigative | F7: I | G7: Likert | H7: I enjoy activities involving asking why things happen. | I7: 1 Strongly Disagree/Dislike | J7: 2 Disagree/Dislike | K7: 3 Neutral/Unsure | L7: 4 Agree/Like | N7: 1-5 Likert: 1=Strongly Disagree/Dislike, 5=Strongly Agree/Like | O7: No | P7: Easy | Q7: 0 | R7: 7 | S7: 18 | T7: Likert 1-5 normalized; reverse if flagged | U7: Investigative Interest | V7: Higher response increases interest score. | W7: RIASEC Interest::Investigative::I | X7: Yes
A8: AQ007 | B8: NPI0031 | C8: 8-12 | D8: RIASEC Interest | E8: Artistic | F8: A | G8: Likert | H8: I enjoy activities involving drawing or design. | I8: 1 Strongly Disagree/Dislike | J8: 2 Disagree/Dislike | K8: 3 Neutral/Unsure | L8: 4 Agree/Like | N8: 1-5 Likert: 1=Strongly Disagree/Dislike, 5=Strongly Agree/Like | O8: No | P8: Easy | Q8: 0 | R8: 7 | S8: 18 | T8: Likert 1-5 normalized; reverse if flagged | U8: Artistic Interest | V8: Higher response increases interest score. | W8: RIASEC Interest::Artistic::A | X8: Yes
A9: AQ008 | B9: NPI0039 | C9: 8-12 | D9: RIASEC Interest | E9: Artistic | F9: A | G9: Likert | H9: I enjoy activities involving aesthetic choices. | I9: 1 Strongly Disagree/Dislike | J9: 2 Disagree/Dislike | K9: 3 Neutral/Unsure | L9: 4 Agree/Like | N9: 1-5 Likert: 1=Strongly Disagree/Dislike, 5=Strongly Agree/Like | O9: No | P9: Medium | Q9: 0 | R9: 10 | S9: 25 | T9: Likert 1-5 normalized; reverse if flagged | U9: Artistic Interest | V9: Higher response increases interest score. | W9: RIASEC Interest::Artistic::A | X9: Yes
A10: AQ009 | B10: NPI0032 | C10: 8-12 | D10: RIASEC Interest | E10: Artistic | F10: A | G10: Likert | H10: I enjoy activities involving music or performance. | I10: 1 Strongly Disagree/Dislike | J10: 2 Disagree/Dislike | K10: 3 Neutral/Unsure | L10: 4 Agree/Like | N10: 1-5 Likert: 1=Strongly Disagree/Dislike, 5=Strongly Agree/Like | O10: No | P10: Easy | Q10: 0 | R10: 7 | S10: 18 | T10: Likert 1-5 normalized; reverse if flagged | U10: Artistic Interest | V10: Higher response increases interest score. | W10: RIASEC Interest::Artistic::A | X10: Yes
A11: AQ010 | B11: NPI0046 | C11: 8-12 | D11: RIASEC Interest | E11: Social | F11: S | G11: Likert | H11: I enjoy activities involving helping classmates. | I11: 1 Strongly Disagree/Dislike | J11: 2 Disagree/Dislike | K11: 3 Neutral/Unsure | L11: 4 Agree/Like | N11: 1-5 Likert: 1=Strongly Disagree/Dislike, 5=Strongly Agree/Like | O11: No | P11: Easy | Q11: 0 | R11: 7 | S11: 18 | T11: Likert 1-5 normalized; reverse if flagged | U11: Social Interest | V11: Higher response increases interest score. | W11: RIASEC Interest::Social::S | X11: Yes
A12: AQ011 | B12: NPI0054 | C12: 8-12 | D12: RIASEC Interest | E12: Social | F12: S | G12: Likert | H12: I enjoy activities involving understanding feelings. | I12: 1 Strongly Disagree/Dislike | J12: 2 Disagree/Dislike | K12: 3 Neutral/Unsure | L12: 4 Agree/Like | N12: 1-5 Likert: 1=Strongly Disagree/Dislike, 5=Strongly Agree/Like | O12: No | P12: Medium | Q12: 0 | R12: 10 | S12: 25 | T12: Likert 1-5 normalized; reverse if flagged | U12: Social Interest | V12: Higher response increases interest score. | W12: RIASEC Interest::Social::S | X12: Yes
A13: AQ012 | B13: NPI0047 | C13: 8-12 | D13: RIASEC Interest | E13: Social | F13: S | G13: Likert | H13: I enjoy activities involving listening to others. | I13: 1 Strongly Disagree/Dislike | J13: 2 Disagree/Dislike | K13: 3 Neutral/Unsure | L13: 4 Agree/Like | N13: 1-5 Likert: 1=Strongly Disagree/Dislike, 5=Strongly Agree/Like | O13: No | P13: Easy | Q13: 0 | R13: 7 | S13: 18 | T13: Likert 1-5 normalized; reverse if flagged | U13: Social Interest | V13: Higher response increases interest score. | W13: RIASEC Interest::Social::S | X13: Yes
... A34: AQ033 | B34: NPI0193 | C34: 8-12 | D34: Big Five Personality | E34: Neuroticism | F34: Neuroticism | G34: Likert | H34: I feel pressure when people expect a lot. | I34: 1 Strongly Disagree/Dislike | J34: 2 Disagree/Dislike | K34: 3 Neutral/Unsure | L34: 4 Agree/Like | N34: 1-5 Likert: 1=Strongly Disagree/Dislike, 5=Strongly Agree/Like | O34: No | P34: Medium | Q34: 0 | R34: 10 | S34: 25 | T34: Likert 1-5 normalized; reverse if flagged | U34: Neuroticism Trait | V34: Higher response increases trait score. | W34: Big Five Personality::Neuroticism::Neuroticism | X34: Yes
A35: AQ034 | B35: NPI0216 | C35: 8-12 | D35: Cognitive Ability | E35: Numerical | F35: Numerical | G35: MCQ | H35: What comes next: 3, 6, 9, 12, ? | I35: 13 | J35: 14 | K35: 15 | L35: 18 | M35: C | N35: MCQ: correct=1, incorrect=0 | O35: No | P35: Medium | Q35: 0 | R35: 10 | S35: 25 | T35: MCQ correct=1, incorrect=0 | U35: Numerical Reasoning | V35: Use accuracy and response time where platform allows. | W35: Cognitive Ability::Numerical::Numerical | X35: Yes
A36: AQ035 | B36: NPI0217 | C36: 8-12 | D36: Cognitive Ability | E36: Numerical | F36: Numerical | G36: MCQ | H36: If 5 notebooks cost ₹150, one costs: | I36: ₹20 | J36: ₹25 | K36: ₹30 | L36: ₹35 | M36: C | N36: MCQ: correct=1, incorrect=0 | O36: No | P36: Medium | Q36: 0 | R36: 10 | S36: 25 | T36: MCQ correct=1, incorrect=0 | U36: Numerical Reasoning | V36: Use accuracy and response time where platform allows. | W36: Cognitive Ability::Numerical::Numerical | X36: Yes
A37: AQ036 | B37: NPI0218 | C37: 8-12 | D37: Cognitive Ability | E37: Numerical | F37: Numerical | G37: MCQ | H37: What is 20% of 250? | I37: 25 | J37: 40 | K37: 50 | L37: 60 | M37: C | N37: MCQ: correct=1, incorrect=0 | O37: No | P37: Medium | Q37: 0 | R37: 10 | S37: 25 | T37: MCQ correct=1, incorrect=0 | U37: Numerical Reasoning | V37: Use accuracy and response time where platform allows. | W37: Cognitive Ability::Numerical::Numerical | X37: Yes
A38: AQ037 | B38: NPI0236 | C38: 8-12 | D38: Cognitive Ability | E38: Logic | F38: Logic | G38: MCQ | H38: All roses are flowers. Which is definitely true? | I38: All roses fade | J38: Some roses fade | K38: Roses are flowers | L38: No flowers are roses | M38: C | N38: MCQ: correct=1, incorrect=0 | O38: No | P38: Medium | Q38: 0 | R38: 10 | S38: 25 | T38: MCQ correct=1, incorrect=0 | U38: Logic Reasoning | V38: Use accuracy and response time where platform allows. | W38: Cognitive Ability::Logic::Logic | X38: Yes
A39: AQ038 | B39: NPI0237 | C39: 8-12 | D39: Cognitive Ability | E39: Logic | F39: Logic | G39: MCQ | H39: Wednesday + 10 days | I39: Friday | J39: Saturday | K39: Sunday | L39: Monday | M39: B | N39: MCQ: correct=1, incorrect=0 | O39: No | P39: Medium | Q39: 0 | R39: 10 | S39: 25 | T39: MCQ correct=1, incorrect=0 | U39: Logic Reasoning | V39: Use accuracy and response time where platform allows. | W39: Cognitive Ability::Logic::Logic | X39: Yes
A40: AQ039 | B40: NPI0238 | C40: 8-12 | D40: Cognitive Ability | E40: Logic | F40: Logic | G40: MCQ | H40: Odd one: Pen, Pencil, Eraser, Mango | I40: Pen | J40: Pencil | K40: Eraser | L40: Mango | M40: D | N40: MCQ: correct=1, incorrect=0 | O40: No | P40: Medium | Q40: 0 | R40: 10 | S40: 25 | T40: MCQ correct=1, incorrect=0 | U40: Logic Reasoning | V40: Use accuracy and response time where platform allows. | W40: Cognitive Ability::Logic::Logic | X40: Yes
A41: AQ040 | B41: NPI0256 | C41: 8-12 | D41: Cognitive Ability | E41: Verbal | F41: Verbal | G41: MCQ | H41: Synonym of brave | I41: Fearful | J41: Courageous | K41: Lazy | L41: Confused | M41: B | N41: MCQ: correct=1, incorrect=0 | O41: No | P41: Medium | Q41: 0 | R41: 10 | S41: 25 | T41: MCQ correct=1, incorrect=0 | U41: Verbal Reasoning | V41: Use accuracy and response time where platform allows. | W41: Cognitive Ability::Verbal::Verbal | X41: Yes
A42: AQ041 | B42: NPI0257 | C42: 8-12 | D42: Cognitive Ability | E42: Verbal | F42: Verbal | G42: MCQ | H42: Antonym of expand | I42: Grow | J42: Increase | K42: Shrink | L42: Open | M42: C | N42: MCQ: correct=1, incorrect=0 | O42: No | P42: Medium | Q42: 0 | R42: 10 | S42: 25 | T42: MCQ correct=1, incorrect=0 | U42: Verbal Reasoning | V42: Use accuracy and response time where platform allows. | W42: Cognitive Ability::Verbal::Verbal | X42: Yes
A43: AQ042 | B43: NPI0258 | C43: 8-12 | D43: Cognitive Ability | E43: Verbal | F43: Verbal | G43: MCQ | H43: Library: people ___ books | I43: eat | J43: borrow | K43: sleep | L43: throw | M43: B | N43: MCQ: correct=1, incorrect=0 | O43: No | P43: Medium | Q43: 0 | R43: 10 | S43: 25 | T43: MCQ correct=1, incorrect=0 | U43: Verbal Reasoning | V43: Use accuracy and response time where platform allows. | W43: Cognitive Ability::Verbal::Verbal | X43: Yes
A44: AQ043 | B44: NPI0276 | C44: 8-12 | D44: Cognitive Ability | E44: Abstract | F44: Abstract | G44: MCQ | H44: ▲ ● ▲ ● ? | I44: ▲ | J44: ● | K44: ■ | L44: ◆ | M44: A | N44: MCQ: correct=1, incorrect=0 | O44: No | P44: Medium | Q44: 0 | R44: 10 | S44: 25 | T44: MCQ correct=1, incorrect=0 | U44: Abstract Reasoning | V44: Use accuracy and response time where platform allows. | W44: Cognitive Ability::Abstract::Abstract | X44: Yes
A45: AQ044 | B45: NPI0277 | C45: 8-12 | D45: Cognitive Ability | E45: Abstract | F45: Abstract | G45: MCQ | H45: A,C,E,G,? | I45: H | J45: I | K45: J | L45: K | M45: B | N45: MCQ: correct=1, incorrect=0 | O45: No | P45: Medium | Q45: 0 | R45: 10 | S45: 25 | T45: MCQ correct=1, incorrect=0 | U45: Abstract Reasoning | V45: Use accuracy and response time where platform allows. | W45: Cognitive Ability::Abstract::Abstract | X45: Yes
A46: AQ045 | B46: NPI0278 | C46: 8-12 | D46: Cognitive Ability | E46: Abstract | F46: Abstract | G46: MCQ | H46: 1,2,4,8,? | I46: 10 | J46: 12 | K46: 14 | L46: 16 | M46: D | N46: MCQ: correct=1, incorrect=0 | O46: No | P46: Medium | Q46: 0 | R46: 10 | S46: 25 | T46: MCQ correct=1, incorrect=0 | U46: Abstract Reasoning | V46: Use accuracy and response time where platform allows. | W46: Cognitive Ability::Abstract::Abstract | X46: Yes
... A49: AQ048 | B49: NPI0298 | C49: 8-12 | D49: Cognitive Ability | E49: Spatial | F49: Spatial | G49: MCQ | H49: Rotated triangle remains | I49: Circle | J49: Triangle | K49: Square | L49: Line | M49: B | N49: MCQ: correct=1, incorrect=0 | O49: No | P49: Medium | Q49: 0 | R49: 10 | S49: 25 | T49: MCQ correct=1, incorrect=0 | U49: Spatial Reasoning | V49: Use accuracy and response time where platform allows. | W49: Cognitive Ability::Spatial::Spatial | X49: Yes
A50: AQ049 | B50: NPI0316 | C50: 8-12 | D50: Emotional Profile | E50: Stress | F50: Stress | G50: Likert | H50: I feel tense before exams. | I50: 1 Strongly Disagree/Dislike | J50: 2 Disagree/Dislike | K50: 3 Neutral/Unsure | L50: 4 Agree/Like | N50: 1-5 Likert: 1=Strongly Disagree/Dislike, 5=Strongly Agree/Like | O50: No | P50: Medium | Q50: 0 | R50: 10 | S50: 25 | T50: Likert 1-5 normalized; reverse if flagged | U50: Stress Indicator | V50: Interpret with student interview and context. | W50: Emotional Profile::Stress::Stress | X50: Yes
A51: AQ050 | B51: NPI0317 | C51: 8-12 | D51: Emotional Profile | E51: Stress | F51: Stress | G51: Likert | H51: I feel overwhelmed by workload. | I51: 1 Strongly Disagree/Dislike | J51: 2 Disagree/Dislike | K51: 3 Neutral/Unsure | L51: 4 Agree/Like | N51: 1-5 Likert: 1=Strongly Disagree/Dislike, 5=Strongly Agree/Like | O51: No | P51: Medium | Q51: 0 | R51: 10 | S51: 25 | T51: Likert 1-5 normalized; reverse if flagged | U51: Stress Indicator | V51: Interpret with student interview and context. | W51: Emotional Profile::Stress::Stress | X51: Yes
A52: AQ051 | B52: NPI0318 | C52: 8-12 | D52: Emotional Profile | E52: Stress | F52: Stress | G52: Likert | H52: I worry about marks after studying. | I52: 1 Strongly Disagree/Dislike | J52: 2 Disagree/Dislike | K52: 3 Neutral/Unsure | L52: 4 Agree/Like | N52: 1-5 Likert: 1=Strongly Disagree/Dislike, 5=Strongly Agree/Like | O52: No | P52: Medium | Q52: 0 | R52: 10 | S52: 25 | T52: Likert 1-5 normalized; reverse if flagged | U52: Stress Indicator | V52: Interpret with student interview and context. | W52: Emotional Profile::Stress::Stress | X52: Yes
A53: AQ052 | B53: NPI0336 | C53: 8-12 | D53: Emotional Profile | E53: Confidence | F53: Confidence | G53: Likert | H53: I believe I can improve. | I53: 1 Strongly Disagree/Dislike | J53: 2 Disagree/Dislike | K53: 3 Neutral/Unsure | L53: 4 Agree/Like | N53: 1-5 Likert: 1=Strongly Disagree/Dislike, 5=Strongly Agree/Like | O53: No | P53: Medium | Q53: 0 | R53: 10 | S53: 25 | T53: Likert 1-5 normalized; reverse if flagged | U53: Confidence Indicator | V53: Interpret with student interview and context. | W53: Emotional Profile::Confidence::Confidence | X53: Yes
A54: AQ053 | B54: NPI0337 | C54: 8-12 | D54: Emotional Profile | E54: Confidence | F54: Confidence | G54: Likert | H54: I feel confident asking doubts. | I54: 1 Strongly Disagree/Dislike | J54: 2 Disagree/Dislike | K54: 3 Neutral/Unsure | L54: 4 Agree/Like | N54: 1-5 Likert: 1=Strongly Disagree/Dislike, 5=Strongly Agree/Like | O54: No | P54: Medium | Q54: 0 | R54: 10 | S54: 25 | T54: Likert 1-5 normalized; reverse if flagged | U54: Confidence Indicator | V54: Interpret with student interview and context. | W54: Emotional Profile::Confidence::Confidence | X54: Yes
A55: AQ054 | B55: NPI0338 | C55: 8-12 | D55: Emotional Profile | E55: Confidence | F55: Confidence | G55: Likert | H55: I trust my ability to learn. | I55: 1 Strongly Disagree/Dislike | J55: 2 Disagree/Dislike | K55: 3 Neutral/Unsure | L55: 4 Agree/Like | N55: 1-5 Likert: 1=Strongly Disagree/Dislike, 5=Strongly Agree/Like | O55: No | P55: Medium | Q55: 0 | R55: 10 | S55: 25 | T55: Likert 1-5 normalized; reverse if flagged | U55: Confidence Indicator | V55: Interpret with student interview and context. | W55: Emotional Profile::Confidence::Confidence | X55: Yes
A56: AQ055 | B56: NPI0356 | C56: 8-12 | D56: Emotional Profile | E56: Resilience | F56: Resilience | G56: Likert | H56: I try again after failure. | I56: 1 Strongly Disagree/Dislike | J56: 2 Disagree/Dislike | K56: 3 Neutral/Unsure | L56: 4 Agree/Like | N56: 1-5 Likert: 1=Strongly Disagree/Dislike, 5=Strongly Agree/Like | O56: No | P56: Medium | Q56: 0 | R56: 10 | S56: 25 | T56: Likert 1-5 normalized; reverse if flagged | U56: Resilience Indicator | V56: Interpret with student interview and context. | W56: Emotional Profile::Resilience::Resilience | X56: Yes
A57: AQ056 | B57: NPI0357 | C57: 8-12 | D57: Emotional Profile | E57: Resilience | F57: Resilience | G57: Likert | H57: I learn from mistakes. | I57: 1 Strongly Disagree/Dislike | J57: 2 Disagree/Dislike | K57: 3 Neutral/Unsure | L57: 4 Agree/Like | N57: 1-5 Likert: 1=Strongly Disagree/Dislike, 5=Strongly Agree/Like | O57: No | P57: Medium | Q57: 0 | R57: 10 | S57: 25 | T57: Likert 1-5 normalized; reverse if flagged | U57: Resilience Indicator | V57: Interpret with student interview and context. | W57: Emotional Profile::Resilience::Resilience | X57: Yes
A58: AQ057 | B58: NPI0358 | C58: 8-12 | D58: Emotional Profile | E58: Resilience | F58: Resilience | G58: Likert | H58: I keep going when difficult. | I58: 1 Strongly Disagree/Dislike | J58: 2 Disagree/Dislike | K58: 3 Neutral/Unsure | L58: 4 Agree/Like | N58: 1-5 Likert: 1=Strongly Disagree/Dislike, 5=Strongly Agree/Like | O58: No | P58: Medium | Q58: 0 | R58: 10 | S58: 25 | T58: Likert 1-5 normalized; reverse if flagged | U58: Resilience Indicator | V58: Interpret with student interview and context. | W58: Emotional Profile::Resilience::Resilience | X58: Yes
A59: AQ058 | B59: NPI0376 | C59: 8-12 | D59: Emotional Profile | E59: Coping | F59: Coping | G59: Likert | H59: I make a plan when stressed. | I59: 1 Strongly Disagree/Dislike | J59: 2 Disagree/Dislike | K59: 3 Neutral/Unsure | L59: 4 Agree/Like | N59: 1-5 Likert: 1=Strongly Disagree/Dislike, 5=Strongly Agree/Like | O59: No | P59: Medium | Q59: 0 | R59: 10 | S59: 25 | T59: Likert 1-5 normalized; reverse if flagged | U59: Coping Indicator | V59: Interpret with student interview and context. | W59: Emotional Profile::Coping::Coping | X59: Yes
A60: AQ059 | B60: NPI0377 | C60: 8-12 | D60: Emotional Profile | E60: Coping | F60: Coping | G60: Likert | H60: I talk to someone trusted. | I60: 1 Strongly Disagree/Dislike | J60: 2 Disagree/Dislike | K60: 3 Neutral/Unsure | L60: 4 Agree/Like | N60: 1-5 Likert: 1=Strongly Disagree/Dislike, 5=Strongly Agree/Like | O60: No | P60: Medium | Q60: 0 | R60: 10 | S60: 25 | T60: Likert 1-5 normalized; reverse if flagged | U60: Coping Indicator | V60: Interpret with student interview and context. | W60: Emotional Profile::Coping::Coping | X60: Yes
A61: AQ060 | B61: NPI0378 | C61: 8-12 | D61: Emotional Profile | E61: Coping | F61: Coping | G61: Likert | H61: I use breaks to refresh. | I61: 1 Strongly Disagree/Dislike | J61: 2 Disagree/Dislike | K61: 3 Neutral/Unsure | L61: 4 Agree/Like | N61: 1-5 Likert: 1=Strongly Disagree/Dislike, 5=Strongly Agree/Like | O61: No | P61: Medium | Q61: 0 | R61: 10 | S61: 25 | T61: Likert 1-5 normalized; reverse if flagged | U61: Coping Indicator | V61: Interpret with student interview and context. | W61: Emotional Profile::Coping::Coping | X61: Yes
... A85: AQ084 | B85: NPI0518 | C85: 8-12 | D85: Validity & Readiness | E85: Validity | F85: Validity | G85: Likert | H85: I selected random answers without reading. | I85: 1 Strongly Disagree/Dislike | J85: 2 Disagree/Dislike | K85: 3 Neutral/Unsure | L85: 4 Agree/Like | N85: 1-5 Likert: 1=Strongly Disagree/Dislike, 5=Strongly Agree/Like | O85: Yes | P85: Easy | Q85: 0 | R85: 7 | S85: 18 | T85: Likert 1-5 normalized; reverse if flagged | U85: Validity | V85: Quality check only. | W85: Validity & Readiness::Validity::Validity | X85: Yes

Sheet Metric_Scoring_Rules
A1: Layer | B1: Metric | C1: Trait_Code | D1: Questions_Used | E1: Source_QIDs | F1: Response_Type | G1: Raw_Score_Range | H1: Normalized_Score_Formula | I1: Low_Band | J1: Moderate_Band | K1: High_Band | L1: Timing_Rule | M1: AI_Interpretation
A2: Additional NeuroPi Indicators | B2: CareerClarity | C2: CareerClarity | D2: I explored career options. | I know subjects linked to goals. | I know my strengths and interests. | E2: NPI0496, NPI0497, NPI0498 | F2: Likert | G2: 3-15 | H2: ((sum_adjusted_likert - 3) / 12) * 100 | I2: 0-39 | J2: 40-69 | K2: 70-100 | L2: High time in 2+ questions = review flag | M2: Additional NeuroPi indicator for readiness, habits, motivation or validity.
A3: Additional NeuroPi Indicators | B3: Motivation | C3: Motivation | D3: I know why studies matter. | I feel motivated by progress. | I set goals. | E3: NPI0456, NPI0457, NPI0458 | F3: Likert | G3: 3-15 | H3: ((sum_adjusted_likert - 3) / 12) * 100 | I3: 0-39 | J3: 40-69 | K3: 70-100 | L3: High time in 2+ questions = review flag | M3: Additional NeuroPi indicator for readiness, habits, motivation or validity.
A4: Additional NeuroPi Indicators | B4: StudyHabits | C4: StudyHabits | D4: I study regularly. | I revise after class. | I keep a weekly plan. | E4: NPI0476, NPI0477, NPI0478 | F4: Likert | G4: 3-15 | H4: ((sum_adjusted_likert - 3) / 12) * 100 | I4: 0-39 | J4: 40-69 | K4: 70-100 | L4: High time in 2+ questions = review flag | M4: Additional NeuroPi indicator for readiness, habits, motivation or validity.
A5: Big Five Personality | B5: Agreeableness | C5: Agreeableness | D5: I try to understand others’ feelings. | I help classmates when I can. | I prefer cooperation over conflict. | E5: NPI0166, NPI0167, NPI0168 | F5: Likert | G5: 3-15 | H5: ((sum_adjusted_likert - 3) / 12) * 100 | I5: 0-39 | J5: 40-69 | K5: 70-100 | L5: High time in 2+ questions = review flag | M5: How does the student behave? Measures personality tendency for counseling interpretation.
A6: Big Five Personality | B6: Conscientiousness | C6: Conscientiousness | D6: I complete assignments on time. | I plan before important tasks. | I keep study materials organized. | E6: NPI0116, NPI0117, NPI0118 | F6: Likert | G6: 3-15 | H6: ((sum_adjusted_likert - 3) / 12) * 100 | I6: 0-39 | J6: 40-69 | K6: 70-100 | L6: High time in 2+ questions = review flag | M6: How does the student behave? Measures personality tendency for counseling interpretation.
A7: Big Five Personality | B7: Extraversion | C7: Extraversion | D7: I feel energized working with others. | I enjoy group discussions. | I like meeting new people. | E7: NPI0141, NPI0142, NPI0143 | F7: Likert | G7: 3-15 | H7: ((sum_adjusted_likert - 3) / 12) * 100 | I7: 0-39 | J7: 40-69 | K7: 70-100 | L7: High time in 2+ questions = review flag | M7: How does the student behave? Measures personality tendency for counseling interpretation.
A8: Big Five Personality | B8: Neuroticism | C8: Neuroticism | D8: I feel worried before exams. | I get upset when I make mistakes. | I feel pressure when people expect a lot. | E8: NPI0191, NPI0192, NPI0193 | F8: Likert | G8: 3-15 | H8: ((sum_adjusted_likert - 3) / 12) * 100 | I8: 0-39 | J8: 40-69 | K8: 70-100 | L8: High time in 2+ questions = review flag | M8: How does the student behave? Measures personality tendency for counseling interpretation.
A9: Big Five Personality | B9: Openness | C9: Openness | D9: I enjoy trying new learning methods. | I enjoy exploring unfamiliar ideas. | I enjoy creative assignments. | E9: NPI0091, NPI0092, NPI0093 | F9: Likert | G9: 3-15 | H9: ((sum_adjusted_likert - 3) / 12) * 100 | I9: 0-39 | J9: 40-69 | K9: 70-100 | L9: High time in 2+ questions = review flag | M9: How does the student behave? Measures personality tendency for counseling interpretation.
A10: Cognitive Ability | B10: Abstract | C10: Abstract | D10: ▲ ● ▲ ● ? | A,C,E,G,? | 1,2,4,8,? | E10: NPI0276, NPI0277, NPI0278 | F10: MCQ | G10: 0-3 | H10: (correct_count / 3) * 100 | I10: 0-39 | J10: 40-69 | K10: 70-100 | L10: High time in 2+ questions = review flag | M10: Can the student do it? Measures performance/ability in this cognitive metric.
A11: Cognitive Ability | B11: Logic | C11: Logic | D11: All roses are flowers. Which is definitely true? | Wednesday + 10 days | Odd one: Pen, Pencil, Eraser, Mango | E11: NPI0236, NPI0237, NPI0238 | F11: MCQ | G11: 0-3 | H11: (correct_count / 3) * 100 | I11: 0-39 | J11: 40-69 | K11: 70-100 | L11: High time in 2+ questions = review flag | M11: Can the student do it? Measures performance/ability in this cognitive metric.
A12: Cognitive Ability | B12: Numerical | C12: Numerical | D12: What comes next: 3, 6, 9, 12, ? | If 5 notebooks cost ₹150, one costs: | What is 20% of 250? | E12: NPI0216, NPI0217, NPI0218 | F12: MCQ | G12: 0-3 | H12: (correct_count / 3) * 100 | I12: 0-39 | J12: 40-69 | K12: 70-100 | L12: High time in 2+ questions = review flag | M12: Can the student do it? Measures performance/ability in this cognitive metric.
... A29: Validity & Readiness | B29: Validity | C29: Validity | D29: I answered these questions honestly. | I read each question carefully before answering. | I selected random answers without reading. | E29: NPI0516, NPI0517, NPI0518 | F29: Likert | G29: 3-15 | H29: ((sum_adjusted_likert - 3) / 12) * 100 | I29: 0-39 | J29: 40-69 | K29: 70-100 | L29: High time in 2+ questions = review flag | M29: Additional NeuroPi indicator for readiness, habits, motivation or validity.

Sheet Student_Response_Template
A1: Student_ID | B1: Assessment_QID | C1: Layer | D1: Metric | E1: Trait_Code | F1: Question_Type | G1: Question | H1: Response | I1: Response_Time_Sec | J1: Auto_Score_0_100 | K1: Time_Band | L1: Review_Flag | M1: Correct_Key | N1: Reverse_Scored | O1: Time_Low_Max | P1: Time_Moderate_Max | Q1: Time_High_Above
B2: AQ001 | C2: RIASEC Interest | D2: Realistic | E2: R | F2: Likert | G2: I enjoy activities involving building or fixing things. | J2: {=IF(H2="","",IF(F2="Likert",IF(N2="Yes",((6-H2)-1)/4*100,(H2-1)/4*100),IF(UPPER(H2)=UPPER(M2),100,0)))} | K2: {=IF(I2="","",IF(I2<=O2,"Low",IF(I2<=P2,"Moderate","High")))} | L2: {=IF(K2="High","Review","")} | N2: No | O2: 0 | P2: 7 | Q2: 18
B3: AQ002 | C3: RIASEC Interest | D3: Realistic | E3: R | F3: Likert | G3: I enjoy activities involving practical experiments. | J3: {=IF(H3="","",IF(F3="Likert",IF(N3="Yes",((6-H3)-1)/4*100,(H3-1)/4*100),IF(UPPER(H3)=UPPER(M3),100,0)))} | K3: {=IF(I3="","",IF(I3<=O3,"Low",IF(I3<=P3,"Moderate","High")))} | L3: {=IF(K3="High","Review","")} | N3: No | O3: 0 | P3: 10 | Q3: 25
B4: AQ003 | C4: RIASEC Interest | D4: Realistic | E4: R | F4: Likert | G4: I enjoy activities involving using tools or equipment. | J4: {=IF(H4="","",IF(F4="Likert",IF(N4="Yes",((6-H4)-1)/4*100,(H4-1)/4*100),IF(UPPER(H4)=UPPER(M4),100,0)))} | K4: {=IF(I4="","",IF(I4<=O4,"Low",IF(I4<=P4,"Moderate","High")))} | L4: {=IF(K4="High","Review","")} | N4: No | O4: 0 | P4: 7 | Q4: 18
B5: AQ004 | C5: RIASEC Interest | D5: Investigative | E5: I | F5: Likert | G5: I enjoy activities involving solving puzzles. | J5: {=IF(H5="","",IF(F5="Likert",IF(N5="Yes",((6-H5)-1)/4*100,(H5-1)/4*100),IF(UPPER(H5)=UPPER(M5),100,0)))} | K5: {=IF(I5="","",IF(I5<=O5,"Low",IF(I5<=P5,"Moderate","High")))} | L5: {=IF(K5="High","Review","")} | N5: No | O5: 0 | P5: 7 | Q5: 18
B6: AQ005 | C6: RIASEC Interest | D6: Investigative | E6: I | F6: Likert | G6: I enjoy activities involving evidence-based decisions. | J6: {=IF(H6="","",IF(F6="Likert",IF(N6="Yes",((6-H6)-1)/4*100,(H6-1)/4*100),IF(UPPER(H6)=UPPER(M6),100,0)))} | K6: {=IF(I6="","",IF(I6<=O6,"Low",IF(I6<=P6,"Moderate","High")))} | L6: {=IF(K6="High","Review","")} | N6: No | O6: 0 | P6: 10 | Q6: 25
B7: AQ006 | C7: RIASEC Interest | D7: Investigative | E7: I | F7: Likert | G7: I enjoy activities involving asking why things happen. | J7: {=IF(H7="","",IF(F7="Likert",IF(N7="Yes",((6-H7)-1)/4*100,(H7-1)/4*100),IF(UPPER(H7)=UPPER(M7),100,0)))} | K7: {=IF(I7="","",IF(I7<=O7,"Low",IF(I7<=P7,"Moderate","High")))} | L7: {=IF(K7="High","Review","")} | N7: No | O7: 0 | P7: 7 | Q7: 18
B8: AQ007 | C8: RIASEC Interest | D8: Artistic | E8: A | F8: Likert | G8: I enjoy activities involving drawing or design. | J8: {=IF(H8="","",IF(F8="Likert",IF(N8="Yes",((6-H8)-1)/4*100,(H8-1)/4*100),IF(UPPER(H8)=UPPER(M8),100,0)))} | K8: {=IF(I8="","",IF(I8<=O8,"Low",IF(I8<=P8,"Moderate","High")))} | L8: {=IF(K8="High","Review","")} | N8: No | O8: 0 | P8: 7 | Q8: 18
B9: AQ008 | C9: RIASEC Interest | D9: Artistic | E9: A | F9: Likert | G9: I enjoy activities involving aesthetic choices. | J9: {=IF(H9="","",IF(F9="Likert",IF(N9="Yes",((6-H9)-1)/4*100,(H9-1)/4*100),IF(UPPER(H9)=UPPER(M9),100,0)))} | K9: {=IF(I9="","",IF(I9<=O9,"Low",IF(I9<=P9,"Moderate","High")))} | L9: {=IF(K9="High","Review","")} | N9: No | O9: 0 | P9: 10 | Q9: 25
B10: AQ009 | C10: RIASEC Interest | D10: Artistic | E10: A | F10: Likert | G10: I enjoy activities involving music or performance. | J10: {=IF(H10="","",IF(F10="Likert",IF(N10="Yes",((6-H10)-1)/4*100,(H10-1)/4*100),IF(UPPER(H10)=UPPER(M10),100,0)))} | K10: {=IF(I10="","",IF(I10<=O10,"Low",IF(I10<=P10,"Moderate","High")))} | L10: {=IF(K10="High","Review","")} | N10: No | O10: 0 | P10: 7 | Q10: 18
B11: AQ010 | C11: RIASEC Interest | D11: Social | E11: S | F11: Likert | G11: I enjoy activities involving helping classmates. | J11: {=IF(H11="","",IF(F11="Likert",IF(N11="Yes",((6-H11)-1)/4*100,(H11-1)/4*100),IF(UPPER(H11)=UPPER(M11),100,0)))} | K11: {=IF(I11="","",IF(I11<=O11,"Low",IF(I11<=P11,"Moderate","High")))} | L11: {=IF(K11="High","Review","")} | N11: No | O11: 0 | P11: 7 | Q11: 18
B12: AQ011 | C12: RIASEC Interest | D12: Social | E12: S | F12: Likert | G12: I enjoy activities involving understanding feelings. | J12: {=IF(H12="","",IF(F12="Likert",IF(N12="Yes",((6-H12)-1)/4*100,(H12-1)/4*100),IF(UPPER(H12)=UPPER(M12),100,0)))} | K12: {=IF(I12="","",IF(I12<=O12,"Low",IF(I12<=P12,"Moderate","High")))} | L12: {=IF(K12="High","Review","")} | N12: No | O12: 0 | P12: 10 | Q12: 25
B13: AQ012 | C13: RIASEC Interest | D13: Social | E13: S | F13: Likert | G13: I enjoy activities involving listening to others. | J13: {=IF(H13="","",IF(F13="Likert",IF(N13="Yes",((6-H13)-1)/4*100,(H13-1)/4*100),IF(UPPER(H13)=UPPER(M13),100,0)))} | K13: {=IF(I13="","",IF(I13<=O13,"Low",IF(I13<=P13,"Moderate","High")))} | L13: {=IF(K13="High","Review","")} | N13: No | O13: 0 | P13: 7 | Q13: 18
... B34: AQ033 | C34: Big Five Personality | D34: Neuroticism | E34: Neuroticism | F34: Likert | G34: I feel pressure when people expect a lot. | J34: {=IF(H34="","",IF(F34="Likert",IF(N34="Yes",((6-H34)-1)/4*100,(H34-1)/4*100),IF(UPPER(H34)=UPPER(M34),100,0)))} | K34: {=IF(I34="","",IF(I34<=O34,"Low",IF(I34<=P34,"Moderate","High")))} | L34: {=IF(K34="High","Review","")} | N34: No | O34: 0 | P34: 10 | Q34: 25
B35: AQ034 | C35: Cognitive Ability | D35: Numerical | E35: Numerical | F35: MCQ | G35: What comes next: 3, 6, 9, 12, ? | J35: {=IF(H35="","",IF(F35="Likert",IF(N35="Yes",((6-H35)-1)/4*100,(H35-1)/4*100),IF(UPPER(H35)=UPPER(M35),100,0)))} | K35: {=IF(I35="","",IF(I35<=O35,"Low",IF(I35<=P35,"Moderate","High")))} | L35: {=IF(K35="High","Review","")} | M35: C | N35: No | O35: 0 | P35: 10 | Q35: 25
B36: AQ035 | C36: Cognitive Ability | D36: Numerical | E36: Numerical | F36: MCQ | G36: If 5 notebooks cost ₹150, one costs: | J36: {=IF(H36="","",IF(F36="Likert",IF(N36="Yes",((6-H36)-1)/4*100,(H36-1)/4*100),IF(UPPER(H36)=UPPER(M36),100,0)))} | K36: {=IF(I36="","",IF(I36<=O36,"Low",IF(I36<=P36,"Moderate","High")))} | L36: {=IF(K36="High","Review","")} | M36: C | N36: No | O36: 0 | P36: 10 | Q36: 25
B37: AQ036 | C37: Cognitive Ability | D37: Numerical | E37: Numerical | F37: MCQ | G37: What is 20% of 250? | J37: {=IF(H37="","",IF(F37="Likert",IF(N37="Yes",((6-H37)-1)/4*100,(H37-1)/4*100),IF(UPPER(H37)=UPPER(M37),100,0)))} | K37: {=IF(I37="","",IF(I37<=O37,"Low",IF(I37<=P37,"Moderate","High")))} | L37: {=IF(K37="High","Review","")} | M37: C | N37: No | O37: 0 | P37: 10 | Q37: 25
B38: AQ037 | C38: Cognitive Ability | D38: Logic | E38: Logic | F38: MCQ | G38: All roses are flowers. Which is definitely true? | J38: {=IF(H38="","",IF(F38="Likert",IF(N38="Yes",((6-H38)-1)/4*100,(H38-1)/4*100),IF(UPPER(H38)=UPPER(M38),100,0)))} | K38: {=IF(I38="","",IF(I38<=O38,"Low",IF(I38<=P38,"Moderate","High")))} | L38: {=IF(K38="High","Review","")} | M38: C | N38: No | O38: 0 | P38: 10 | Q38: 25
B39: AQ038 | C39: Cognitive Ability | D39: Logic | E39: Logic | F39: MCQ | G39: Wednesday + 10 days | J39: {=IF(H39="","",IF(F39="Likert",IF(N39="Yes",((6-H39)-1)/4*100,(H39-1)/4*100),IF(UPPER(H39)=UPPER(M39),100,0)))} | K39: {=IF(I39="","",IF(I39<=O39,"Low",IF(I39<=P39,"Moderate","High")))} | L39: {=IF(K39="High","Review","")} | M39: B | N39: No | O39: 0 | P39: 10 | Q39: 25
B40: AQ039 | C40: Cognitive Ability | D40: Logic | E40: Logic | F40: MCQ | G40: Odd one: Pen, Pencil, Eraser, Mango | J40: {=IF(H40="","",IF(F40="Likert",IF(N40="Yes",((6-H40)-1)/4*100,(H40-1)/4*100),IF(UPPER(H40)=UPPER(M40),100,0)))} | K40: {=IF(I40="","",IF(I40<=O40,"Low",IF(I40<=P40,"Moderate","High")))} | L40: {=IF(K40="High","Review","")} | M40: D | N40: No | O40: 0 | P40: 10 | Q40: 25
B41: AQ040 | C41: Cognitive Ability | D41: Verbal | E41: Verbal | F41: MCQ | G41: Synonym of brave | J41: {=IF(H41="","",IF(F41="Likert",IF(N41="Yes",((6-H41)-1)/4*100,(H41-1)/4*100),IF(UPPER(H41)=UPPER(M41),100,0)))} | K41: {=IF(I41="","",IF(I41<=O41,"Low",IF(I41<=P41,"Moderate","High")))} | L41: {=IF(K41="High","Review","")} | M41: B | N41: No | O41: 0 | P41: 10 | Q41: 25
B42: AQ041 | C42: Cognitive Ability | D42: Verbal | E42: Verbal | F42: MCQ | G42: Antonym of expand | J42: {=IF(H42="","",IF(F42="Likert",IF(N42="Yes",((6-H42)-1)/4*100,(H42-1)/4*100),IF(UPPER(H42)=UPPER(M42),100,0)))} | K42: {=IF(I42="","",IF(I42<=O42,"Low",IF(I42<=P42,"Moderate","High")))} | L42: {=IF(K42="High","Review","")} | M42: C | N42: No | O42: 0 | P42: 10 | Q42: 25
B43: AQ042 | C43: Cognitive Ability | D43: Verbal | E43: Verbal | F43: MCQ | G43: Library: people ___ books | J43: {=IF(H43="","",IF(F43="Likert",IF(N43="Yes",((6-H43)-1)/4*100,(H43-1)/4*100),IF(UPPER(H43)=UPPER(M43),100,0)))} | K43: {=IF(I43="","",IF(I43<=O43,"Low",IF(I43<=P43,"Moderate","High")))} | L43: {=IF(K43="High","Review","")} | M43: B | N43: No | O43: 0 | P43: 10 | Q43: 25
B44: AQ043 | C44: Cognitive Ability | D44: Abstract | E44: Abstract | F44: MCQ | G44: ▲ ● ▲ ● ? | J44: {=IF(H44="","",IF(F44="Likert",IF(N44="Yes",((6-H44)-1)/4*100,(H44-1)/4*100),IF(UPPER(H44)=UPPER(M44),100,0)))} | K44: {=IF(I44="","",IF(I44<=O44,"Low",IF(I44<=P44,"Moderate","High")))} | L44: {=IF(K44="High","Review","")} | M44: A | N44: No | O44: 0 | P44: 10 | Q44: 25
B45: AQ044 | C45: Cognitive Ability | D45: Abstract | E45: Abstract | F45: MCQ | G45: A,C,E,G,? | J45: {=IF(H45="","",IF(F45="Likert",IF(N45="Yes",((6-H45)-1)/4*100,(H45-1)/4*100),IF(UPPER(H45)=UPPER(M45),100,0)))} | K45: {=IF(I45="","",IF(I45<=O45,"Low",IF(I45<=P45,"Moderate","High")))} | L45: {=IF(K45="High","Review","")} | M45: B | N45: No | O45: 0 | P45: 10 | Q45: 25
B46: AQ045 | C46: Cognitive Ability | D46: Abstract | E46: Abstract | F46: MCQ | G46: 1,2,4,8,? | J46: {=IF(H46="","",IF(F46="Likert",IF(N46="Yes",((6-H46)-1)/4*100,(H46-1)/4*100),IF(UPPER(H46)=UPPER(M46),100,0)))} | K46: {=IF(I46="","",IF(I46<=O46,"Low",IF(I46<=P46,"Moderate","High")))} | L46: {=IF(K46="High","Review","")} | M46: D | N46: No | O46: 0 | P46: 10 | Q46: 25
... B49: AQ048 | C49: Cognitive Ability | D49: Spatial | E49: Spatial | F49: MCQ | G49: Rotated triangle remains | J49: {=IF(H49="","",IF(F49="Likert",IF(N49="Yes",((6-H49)-1)/4*100,(H49-1)/4*100),IF(UPPER(H49)=UPPER(M49),100,0)))} | K49: {=IF(I49="","",IF(I49<=O49,"Low",IF(I49<=P49,"Moderate","High")))} | L49: {=IF(K49="High","Review","")} | M49: B | N49: No | O49: 0 | P49: 10 | Q49: 25
B50: AQ049 | C50: Emotional Profile | D50: Stress | E50: Stress | F50: Likert | G50: I feel tense before exams. | J50: {=IF(H50="","",IF(F50="Likert",IF(N50="Yes",((6-H50)-1)/4*100,(H50-1)/4*100),IF(UPPER(H50)=UPPER(M50),100,0)))} | K50: {=IF(I50="","",IF(I50<=O50,"Low",IF(I50<=P50,"Moderate","High")))} | L50: {=IF(K50="High","Review","")} | N50: No | O50: 0 | P50: 10 | Q50: 25
B51: AQ050 | C51: Emotional Profile | D51: Stress | E51: Stress | F51: Likert | G51: I feel overwhelmed by workload. | J51: {=IF(H51="","",IF(F51="Likert",IF(N51="Yes",((6-H51)-1)/4*100,(H51-1)/4*100),IF(UPPER(H51)=UPPER(M51),100,0)))} | K51: {=IF(I51="","",IF(I51<=O51,"Low",IF(I51<=P51,"Moderate","High")))} | L51: {=IF(K51="High","Review","")} | N51: No | O51: 0 | P51: 10 | Q51: 25
B52: AQ051 | C52: Emotional Profile | D52: Stress | E52: Stress | F52: Likert | G52: I worry about marks after studying. | J52: {=IF(H52="","",IF(F52="Likert",IF(N52="Yes",((6-H52)-1)/4*100,(H52-1)/4*100),IF(UPPER(H52)=UPPER(M52),100,0)))} | K52: {=IF(I52="","",IF(I52<=O52,"Low",IF(I52<=P52,"Moderate","High")))} | L52: {=IF(K52="High","Review","")} | N52: No | O52: 0 | P52: 10 | Q52: 25
B53: AQ052 | C53: Emotional Profile | D53: Confidence | E53: Confidence | F53: Likert | G53: I believe I can improve. | J53: {=IF(H53="","",IF(F53="Likert",IF(N53="Yes",((6-H53)-1)/4*100,(H53-1)/4*100),IF(UPPER(H53)=UPPER(M53),100,0)))} | K53: {=IF(I53="","",IF(I53<=O53,"Low",IF(I53<=P53,"Moderate","High")))} | L53: {=IF(K53="High","Review","")} | N53: No | O53: 0 | P53: 10 | Q53: 25
B54: AQ053 | C54: Emotional Profile | D54: Confidence | E54: Confidence | F54: Likert | G54: I feel confident asking doubts. | J54: {=IF(H54="","",IF(F54="Likert",IF(N54="Yes",((6-H54)-1)/4*100,(H54-1)/4*100),IF(UPPER(H54)=UPPER(M54),100,0)))} | K54: {=IF(I54="","",IF(I54<=O54,"Low",IF(I54<=P54,"Moderate","High")))} | L54: {=IF(K54="High","Review","")} | N54: No | O54: 0 | P54: 10 | Q54: 25
B55: AQ054 | C55: Emotional Profile | D55: Confidence | E55: Confidence | F55: Likert | G55: I trust my ability to learn. | J55: {=IF(H55="","",IF(F55="Likert",IF(N55="Yes",((6-H55)-1)/4*100,(H55-1)/4*100),IF(UPPER(H55)=UPPER(M55),100,0)))} | K55: {=IF(I55="","",IF(I55<=O55,"Low",IF(I55<=P55,"Moderate","High")))} | L55: {=IF(K55="High","Review","")} | N55: No | O55: 0 | P55: 10 | Q55: 25
B56: AQ055 | C56: Emotional Profile | D56: Resilience | E56: Resilience | F56: Likert | G56: I try again after failure. | J56: {=IF(H56="","",IF(F56="Likert",IF(N56="Yes",((6-H56)-1)/4*100,(H56-1)/4*100),IF(UPPER(H56)=UPPER(M56),100,0)))} | K56: {=IF(I56="","",IF(I56<=O56,"Low",IF(I56<=P56,"Moderate","High")))} | L56: {=IF(K56="High","Review","")} | N56: No | O56: 0 | P56: 10 | Q56: 25
B57: AQ056 | C57: Emotional Profile | D57: Resilience | E57: Resilience | F57: Likert | G57: I learn from mistakes. | J57: {=IF(H57="","",IF(F57="Likert",IF(N57="Yes",((6-H57)-1)/4*100,(H57-1)/4*100),IF(UPPER(H57)=UPPER(M57),100,0)))} | K57: {=IF(I57="","",IF(I57<=O57,"Low",IF(I57<=P57,"Moderate","High")))} | L57: {=IF(K57="High","Review","")} | N57: No | O57: 0 | P57: 10 | Q57: 25
B58: AQ057 | C58: Emotional Profile | D58: Resilience | E58: Resilience | F58: Likert | G58: I keep going when difficult. | J58: {=IF(H58="","",IF(F58="Likert",IF(N58="Yes",((6-H58)-1)/4*100,(H58-1)/4*100),IF(UPPER(H58)=UPPER(M58),100,0)))} | K58: {=IF(I58="","",IF(I58<=O58,"Low",IF(I58<=P58,"Moderate","High")))} | L58: {=IF(K58="High","Review","")} | N58: No | O58: 0 | P58: 10 | Q58: 25
B59: AQ058 | C59: Emotional Profile | D59: Coping | E59: Coping | F59: Likert | G59: I make a plan when stressed. | J59: {=IF(H59="","",IF(F59="Likert",IF(N59="Yes",((6-H59)-1)/4*100,(H59-1)/4*100),IF(UPPER(H59)=UPPER(M59),100,0)))} | K59: {=IF(I59="","",IF(I59<=O59,"Low",IF(I59<=P59,"Moderate","High")))} | L59: {=IF(K59="High","Review","")} | N59: No | O59: 0 | P59: 10 | Q59: 25
B60: AQ059 | C60: Emotional Profile | D60: Coping | E60: Coping | F60: Likert | G60: I talk to someone trusted. | J60: {=IF(H60="","",IF(F60="Likert",IF(N60="Yes",((6-H60)-1)/4*100,(H60-1)/4*100),IF(UPPER(H60)=UPPER(M60),100,0)))} | K60: {=IF(I60="","",IF(I60<=O60,"Low",IF(I60<=P60,"Moderate","High")))} | L60: {=IF(K60="High","Review","")} | N60: No | O60: 0 | P60: 10 | Q60: 25
B61: AQ060 | C61: Emotional Profile | D61: Coping | E61: Coping | F61: Likert | G61: I use breaks to refresh. | J61: {=IF(H61="","",IF(F61="Likert",IF(N61="Yes",((6-H61)-1)/4*100,(H61-1)/4*100),IF(UPPER(H61)=UPPER(M61),100,0)))} | K61: {=IF(I61="","",IF(I61<=O61,"Low",IF(I61<=P61,"Moderate","High")))} | L61: {=IF(K61="High","Review","")} | N61: No | O61: 0 | P61: 10 | Q61: 25
... B85: AQ084 | C85: Validity & Readiness | D85: Validity | E85: Validity | F85: Likert | G85: I selected random answers without reading. | J85: {=IF(H85="","",IF(F85="Likert",IF(N85="Yes",((6-H85)-1)/4*100,(H85-1)/4*100),IF(UPPER(H85)=UPPER(M85),100,0)))} | K85: {=IF(I85="","",IF(I85<=O85,"Low",IF(I85<=P85,"Moderate","High")))} | L85: {=IF(K85="High","Review","")} | N85: Yes | O85: 0 | P85: 7 | Q85: 18

Sheet Auto_Score_Summary
A1: Layer | B1: Metric | C1: Trait_Code | D1: Average_Score_0_100 | E1: Band | F1: Avg_Time_Sec | G1: High_Time_Count | H1: AI_Flag | I1: Interpretation | K1: Dashboard formulas are in README.
A2: Additional NeuroPi Indicators | B2: CareerClarity | C2: CareerClarity | D2: {=_xlfn.IFERROR(_xlfn.AVERAGEIFS('Student_Response_Template'!$J1:$J86,'Student_Response_Template'!$C1:$C86,A2,'Student_Response_Template'!$D1:$D86,B2,'Student_Response_Template'!$E1:$E86,C2),"")} | E2: {=IF(D2="","",IF(D2<40,"Low",IF(D2<70,"Moderate","High")))} | F2: {=_xlfn.IFERROR(_xlfn.AVERAGEIFS('Student_Response_Template'!$I1:$I86,'Student_Response_Template'!$C1:$C86,A2,'Student_Response_Template'!$D1:$D86,B2,'Student_Response_Template'!$E1:$E86,C2),"")} | G2: {=_xlfn.COUNTIFS('Student_Response_Template'!$C1:$C86,A2,'Student_Response_Template'!$D1:$D86,B2,'Student_Response_Template'!$E1:$E86,C2,'Student_Response_Template'!$K1:$K86,"High")} -> 0 | H2: {=IF(D2="","",IF(G2>=2,"Timing Review",IF(D2<40,"Support Needed","OK")))} | I2: CareerClarity developmental support indicator.
A3: Additional NeuroPi Indicators | B3: Motivation | C3: Motivation | D3: {=_xlfn.IFERROR(_xlfn.AVERAGEIFS('Student_Response_Template'!$J1:$J86,'Student_Response_Template'!$C1:$C86,A3,'Student_Response_Template'!$D1:$D86,B3,'Student_Response_Template'!$E1:$E86,C3),"")} | E3: {=IF(D3="","",IF(D3<40,"Low",IF(D3<70,"Moderate","High")))} | F3: {=_xlfn.IFERROR(_xlfn.AVERAGEIFS('Student_Response_Template'!$I1:$I86,'Student_Response_Template'!$C1:$C86,A3,'Student_Response_Template'!$D1:$D86,B3,'Student_Response_Template'!$E1:$E86,C3),"")} | G3: {=_xlfn.COUNTIFS('Student_Response_Template'!$C1:$C86,A3,'Student_Response_Template'!$D1:$D86,B3,'Student_Response_Template'!$E1:$E86,C3,'Student_Response_Template'!$K1:$K86,"High")} -> 0 | H3: {=IF(D3="","",IF(G3>=2,"Timing Review",IF(D3<40,"Support Needed","OK")))} | I3: Motivation developmental support indicator.
A4: Additional NeuroPi Indicators | B4: StudyHabits | C4: StudyHabits | D4: {=_xlfn.IFERROR(_xlfn.AVERAGEIFS('Student_Response_Template'!$J1:$J86,'Student_Response_Template'!$C1:$C86,A4,'Student_Response_Template'!$D1:$D86,B4,'Student_Response_Template'!$E1:$E86,C4),"")} | E4: {=IF(D4="","",IF(D4<40,"Low",IF(D4<70,"Moderate","High")))} | F4: {=_xlfn.IFERROR(_xlfn.AVERAGEIFS('Student_Response_Template'!$I1:$I86,'Student_Response_Template'!$C1:$C86,A4,'Student_Response_Template'!$D1:$D86,B4,'Student_Response_Template'!$E1:$E86,C4),"")} | G4: {=_xlfn.COUNTIFS('Student_Response_Template'!$C1:$C86,A4,'Student_Response_Template'!$D1:$D86,B4,'Student_Response_Template'!$E1:$E86,C4,'Student_Response_Template'!$K1:$K86,"High")} -> 0 | H4: {=IF(D4="","",IF(G4>=2,"Timing Review",IF(D4<40,"Support Needed","OK")))} | I4: StudyHabits developmental support indicator.
A5: Big Five Personality | B5: Agreeableness | C5: Agreeableness | D5: {=_xlfn.IFERROR(_xlfn.AVERAGEIFS('Student_Response_Template'!$J1:$J86,'Student_Response_Template'!$C1:$C86,A5,'Student_Response_Template'!$D1:$D86,B5,'Student_Response_Template'!$E1:$E86,C5),"")} | E5: {=IF(D5="","",IF(D5<40,"Low",IF(D5<70,"Moderate","High")))} | F5: {=_xlfn.IFERROR(_xlfn.AVERAGEIFS('Student_Response_Template'!$I1:$I86,'Student_Response_Template'!$C1:$C86,A5,'Student_Response_Template'!$D1:$D86,B5,'Student_Response_Template'!$E1:$E86,C5),"")} | G5: {=_xlfn.COUNTIFS('Student_Response_Template'!$C1:$C86,A5,'Student_Response_Template'!$D1:$D86,B5,'Student_Response_Template'!$E1:$E86,C5,'Student_Response_Template'!$K1:$K86,"High")} -> 0 | H5: {=IF(D5="","",IF(G5>=2,"Timing Review",IF(D5<40,"Support Needed","OK")))} | I5: Agreeableness personality tendency.
A6: Big Five Personality | B6: Conscientiousness | C6: Conscientiousness | D6: {=_xlfn.IFERROR(_xlfn.AVERAGEIFS('Student_Response_Template'!$J1:$J86,'Student_Response_Template'!$C1:$C86,A6,'Student_Response_Template'!$D1:$D86,B6,'Student_Response_Template'!$E1:$E86,C6),"")} | E6: {=IF(D6="","",IF(D6<40,"Low",IF(D6<70,"Moderate","High")))} | F6: {=_xlfn.IFERROR(_xlfn.AVERAGEIFS('Student_Response_Template'!$I1:$I86,'Student_Response_Template'!$C1:$C86,A6,'Student_Response_Template'!$D1:$D86,B6,'Student_Response_Template'!$E1:$E86,C6),"")} | G6: {=_xlfn.COUNTIFS('Student_Response_Template'!$C1:$C86,A6,'Student_Response_Template'!$D1:$D86,B6,'Student_Response_Template'!$E1:$E86,C6,'Student_Response_Template'!$K1:$K86,"High")} -> 0 | H6: {=IF(D6="","",IF(G6>=2,"Timing Review",IF(D6<40,"Support Needed","OK")))} | I6: Conscientiousness personality tendency.
A7: Big Five Personality | B7: Extraversion | C7: Extraversion | D7: {=_xlfn.IFERROR(_xlfn.AVERAGEIFS('Student_Response_Template'!$J1:$J86,'Student_Response_Template'!$C1:$C86,A7,'Student_Response_Template'!$D1:$D86,B7,'Student_Response_Template'!$E1:$E86,C7),"")} | E7: {=IF(D7="","",IF(D7<40,"Low",IF(D7<70,"Moderate","High")))} | F7: {=_xlfn.IFERROR(_xlfn.AVERAGEIFS('Student_Response_Template'!$I1:$I86,'Student_Response_Template'!$C1:$C86,A7,'Student_Response_Template'!$D1:$D86,B7,'Student_Response_Template'!$E1:$E86,C7),"")} | G7: {=_xlfn.COUNTIFS('Student_Response_Template'!$C1:$C86,A7,'Student_Response_Template'!$D1:$D86,B7,'Student_Response_Template'!$E1:$E86,C7,'Student_Response_Template'!$K1:$K86,"High")} -> 0 | H7: {=IF(D7="","",IF(G7>=2,"Timing Review",IF(D7<40,"Support Needed","OK")))} | I7: Extraversion personality tendency.
A8: Big Five Personality | B8: Neuroticism | C8: Neuroticism | D8: {=_xlfn.IFERROR(_xlfn.AVERAGEIFS('Student_Response_Template'!$J1:$J86,'Student_Response_Template'!$C1:$C86,A8,'Student_Response_Template'!$D1:$D86,B8,'Student_Response_Template'!$E1:$E86,C8),"")} | E8: {=IF(D8="","",IF(D8<40,"Low",IF(D8<70,"Moderate","High")))} | F8: {=_xlfn.IFERROR(_xlfn.AVERAGEIFS('Student_Response_Template'!$I1:$I86,'Student_Response_Template'!$C1:$C86,A8,'Student_Response_Template'!$D1:$D86,B8,'Student_Response_Template'!$E1:$E86,C8),"")} | G8: {=_xlfn.COUNTIFS('Student_Response_Template'!$C1:$C86,A8,'Student_Response_Template'!$D1:$D86,B8,'Student_Response_Template'!$E1:$E86,C8,'Student_Response_Template'!$K1:$K86,"High")} -> 0 | H8: {=IF(D8="","",IF(G8>=2,"Timing Review",IF(D8<40,"Support Needed","OK")))} | I8: Neuroticism personality tendency.
A9: Big Five Personality | B9: Openness | C9: Openness | D9: {=_xlfn.IFERROR(_xlfn.AVERAGEIFS('Student_Response_Template'!$J1:$J86,'Student_Response_Template'!$C1:$C86,A9,'Student_Response_Template'!$D1:$D86,B9,'Student_Response_Template'!$E1:$E86,C9),"")} | E9: {=IF(D9="","",IF(D9<40,"Low",IF(D9<70,"Moderate","High")))} | F9: {=_xlfn.IFERROR(_xlfn.AVERAGEIFS('Student_Response_Template'!$I1:$I86,'Student_Response_Template'!$C1:$C86,A9,'Student_Response_Template'!$D1:$D86,B9,'Student_Response_Template'!$E1:$E86,C9),"")} | G9: {=_xlfn.COUNTIFS('Student_Response_Template'!$C1:$C86,A9,'Student_Response_Template'!$D1:$D86,B9,'Student_Response_Template'!$E1:$E86,C9,'Student_Response_Template'!$K1:$K86,"High")} -> 0 | H9: {=IF(D9="","",IF(G9>=2,"Timing Review",IF(D9<40,"Support Needed","OK")))} | I9: Openness personality tendency.
A10: Cognitive Ability | B10: Abstract | C10: Abstract | D10: {=_xlfn.IFERROR(_xlfn.AVERAGEIFS('Student_Response_Template'!$J1:$J86,'Student_Response_Template'!$C1:$C86,A10,'Student_Response_Template'!$D1:$D86,B10,'Student_Response_Template'!$E1:$E86,C10),"")} | E10: {=IF(D10="","",IF(D10<40,"Low",IF(D10<70,"Moderate","High")))} | F10: {=_xlfn.IFERROR(_xlfn.AVERAGEIFS('Student_Response_Template'!$I1:$I86,'Student_Response_Template'!$C1:$C86,A10,'Student_Response_Template'!$D1:$D86,B10,'Student_Response_Template'!$E1:$E86,C10),"")} | G10: {=_xlfn.COUNTIFS('Student_Response_Template'!$C1:$C86,A10,'Student_Response_Template'!$D1:$D86,B10,'Student_Response_Template'!$E1:$E86,C10,'Student_Response_Template'!$K1:$K86,"High")} -> 0 | H10: {=IF(D10="","",IF(G10>=2,"Timing Review",IF(D10<40,"Support Needed","OK")))} | I10: Abstract cognitive performance.
A11: Cognitive Ability | B11: Logic | C11: Logic | D11: {=_xlfn.IFERROR(_xlfn.AVERAGEIFS('Student_Response_Template'!$J1:$J86,'Student_Response_Template'!$C1:$C86,A11,'Student_Response_Template'!$D1:$D86,B11,'Student_Response_Template'!$E1:$E86,C11),"")} | E11: {=IF(D11="","",IF(D11<40,"Low",IF(D11<70,"Moderate","High")))} | F11: {=_xlfn.IFERROR(_xlfn.AVERAGEIFS('Student_Response_Template'!$I1:$I86,'Student_Response_Template'!$C1:$C86,A11,'Student_Response_Template'!$D1:$D86,B11,'Student_Response_Template'!$E1:$E86,C11),"")} | G11: {=_xlfn.COUNTIFS('Student_Response_Template'!$C1:$C86,A11,'Student_Response_Template'!$D1:$D86,B11,'Student_Response_Template'!$E1:$E86,C11,'Student_Response_Template'!$K1:$K86,"High")} -> 0 | H11: {=IF(D11="","",IF(G11>=2,"Timing Review",IF(D11<40,"Support Needed","OK")))} | I11: Logic cognitive performance.
A12: Cognitive Ability | B12: Numerical | C12: Numerical | D12: {=_xlfn.IFERROR(_xlfn.AVERAGEIFS('Student_Response_Template'!$J1:$J86,'Student_Response_Template'!$C1:$C86,A12,'Student_Response_Template'!$D1:$D86,B12,'Student_Response_Template'!$E1:$E86,C12),"")} | E12: {=IF(D12="","",IF(D12<40,"Low",IF(D12<70,"Moderate","High")))} | F12: {=_xlfn.IFERROR(_xlfn.AVERAGEIFS('Student_Response_Template'!$I1:$I86,'Student_Response_Template'!$C1:$C86,A12,'Student_Response_Template'!$D1:$D86,B12,'Student_Response_Template'!$E1:$E86,C12),"")} | G12: {=_xlfn.COUNTIFS('Student_Response_Template'!$C1:$C86,A12,'Student_Response_Template'!$D1:$D86,B12,'Student_Response_Template'!$E1:$E86,C12,'Student_Response_Template'!$K1:$K86,"High")} -> 0 | H12: {=IF(D12="","",IF(G12>=2,"Timing Review",IF(D12<40,"Support Needed","OK")))} | I12: Numerical cognitive performance.
A13: Cognitive Ability | B13: Spatial | C13: Spatial | D13: {=_xlfn.IFERROR(_xlfn.AVERAGEIFS('Student_Response_Template'!$J1:$J86,'Student_Response_Template'!$C1:$C86,A13,'Student_Response_Template'!$D1:$D86,B13,'Student_Response_Template'!$E1:$E86,C13),"")} | E13: {=IF(D13="","",IF(D13<40,"Low",IF(D13<70,"Moderate","High")))} | F13: {=_xlfn.IFERROR(_xlfn.AVERAGEIFS('Student_Response_Template'!$I1:$I86,'Student_Response_Template'!$C1:$C86,A13,'Student_Response_Template'!$D1:$D86,B13,'Student_Response_Template'!$E1:$E86,C13),"")} | G13: {=_xlfn.COUNTIFS('Student_Response_Template'!$C1:$C86,A13,'Student_Response_Template'!$D1:$D86,B13,'Student_Response_Template'!$E1:$E86,C13,'Student_Response_Template'!$K1:$K86,"High")} -> 0 | H13: {=IF(D13="","",IF(G13>=2,"Timing Review",IF(D13<40,"Support Needed","OK")))} | I13: Spatial cognitive performance.
A14: Cognitive Ability | B14: Verbal | C14: Verbal | D14: {=_xlfn.IFERROR(_xlfn.AVERAGEIFS('Student_Response_Template'!$J1:$J86,'Student_Response_Template'!$C1:$C86,A14,'Student_Response_Template'!$D1:$D86,B14,'Student_Response_Template'!$E1:$E86,C14),"")} | E14: {=IF(D14="","",IF(D14<40,"Low",IF(D14<70,"Moderate","High")))} | F14: {=_xlfn.IFERROR(_xlfn.AVERAGEIFS('Student_Response_Template'!$I1:$I86,'Student_Response_Template'!$C1:$C86,A14,'Student_Response_Template'!$D1:$D86,B14,'Student_Response_Template'!$E1:$E86,C14),"")} | G14: {=_xlfn.COUNTIFS('Student_Response_Template'!$C1:$C86,A14,'Student_Response_Template'!$D1:$D86,B14,'Student_Response_Template'!$E1:$E86,C14,'Student_Response_Template'!$K1:$K86,"High")} -> 0 | H14: {=IF(D14="","",IF(G14>=2,"Timing Review",IF(D14<40,"Support Needed","OK")))} | I14: Verbal cognitive performance.
A15: Emotional Profile | B15: Confidence | C15: Confidence | D15: {=_xlfn.IFERROR(_xlfn.AVERAGEIFS('Student_Response_Template'!$J1:$J86,'Student_Response_Template'!$C1:$C86,A15,'Student_Response_Template'!$D1:$D86,B15,'Student_Response_Template'!$E1:$E86,C15),"")} | E15: {=IF(D15="","",IF(D15<40,"Low",IF(D15<70,"Moderate","High")))} | F15: {=_xlfn.IFERROR(_xlfn.AVERAGEIFS('Student_Response_Template'!$I1:$I86,'Student_Response_Template'!$C1:$C86,A15,'Student_Response_Template'!$D1:$D86,B15,'Student_Response_Template'!$E1:$E86,C15),"")} | G15: {=_xlfn.COUNTIFS('Student_Response_Template'!$C1:$C86,A15,'Student_Response_Template'!$D1:$D86,B15,'Student_Response_Template'!$E1:$E86,C15,'Student_Response_Template'!$K1:$K86,"High")} -> 0 | H15: {=IF(D15="","",IF(G15>=2,"Timing Review",IF(D15<40,"Support Needed","OK")))} | I15: Confidence emotional sustainability indicator.
A16: Emotional Profile | B16: Coping | C16: Coping | D16: {=_xlfn.IFERROR(_xlfn.AVERAGEIFS('Student_Response_Template'!$J1:$J86,'Student_Response_Template'!$C1:$C86,A16,'Student_Response_Template'!$D1:$D86,B16,'Student_Response_Template'!$E1:$E86,C16),"")} | E16: {=IF(D16="","",IF(D16<40,"Low",IF(D16<70,"Moderate","High")))} | F16: {=_xlfn.IFERROR(_xlfn.AVERAGEIFS('Student_Response_Template'!$I1:$I86,'Student_Response_Template'!$C1:$C86,A16,'Student_Response_Template'!$D1:$D86,B16,'Student_Response_Template'!$E1:$E86,C16),"")} | G16: {=_xlfn.COUNTIFS('Student_Response_Template'!$C1:$C86,A16,'Student_Response_Template'!$D1:$D86,B16,'Student_Response_Template'!$E1:$E86,C16,'Student_Response_Template'!$K1:$K86,"High")} -> 0 | H16: {=IF(D16="","",IF(G16>=2,"Timing Review",IF(D16<40,"Support Needed","OK")))} | I16: Coping emotional sustainability indicator.
A17: Emotional Profile | B17: Resilience | C17: Resilience | D17: {=_xlfn.IFERROR(_xlfn.AVERAGEIFS('Student_Response_Template'!$J1:$J86,'Student_Response_Template'!$C1:$C86,A17,'Student_Response_Template'!$D1:$D86,B17,'Student_Response_Template'!$E1:$E86,C17),"")} | E17: {=IF(D17="","",IF(D17<40,"Low",IF(D17<70,"Moderate","High")))} | F17: {=_xlfn.IFERROR(_xlfn.AVERAGEIFS('Student_Response_Template'!$I1:$I86,'Student_Response_Template'!$C1:$C86,A17,'Student_Response_Template'!$D1:$D86,B17,'Student_Response_Template'!$E1:$E86,C17),"")} | G17: {=_xlfn.COUNTIFS('Student_Response_Template'!$C1:$C86,A17,'Student_Response_Template'!$D1:$D86,B17,'Student_Response_Template'!$E1:$E86,C17,'Student_Response_Template'!$K1:$K86,"High")} -> 0 | H17: {=IF(D17="","",IF(G17>=2,"Timing Review",IF(D17<40,"Support Needed","OK")))} | I17: Resilience emotional sustainability indicator.
