Workbook

Sheet Export Summary
B3: This document was exported from Numbers. Each table was converted to an Excel worksheet. All other objects on each Numbers sheet were placed on separate worksheets. Please be aware that formula calculations may differ in Excel.
B7: Numbers Sheet Name | C7: Numbers Table Name | D7: Excel Worksheet Name
B9: Instructions
C10: Table 1 | D10: Instructions
B11: Scoring_Map
C12: Table 1 | D12: Scoring_Map
B13: Question_Bank
C14: Table 1 | D14: Question_Bank
B15: Student_Responses
C16: Table 1 | D16: Student_Responses
B17: Score_Summary
C18: Table 1 | D18: Score_Summary
B19: Dashboard
C20: Table 1 | D20: Dashboard
B21: Report_Summary
C22: Table 1 | D22: Report_Summary
B23: Answer_Key
C24: Table 1 | D24: Answer_Key
B25: Administration_Guide
C26: Table 1 | D26: Administration_Guide
B27: Short_Form_Blueprint
C28: Table 1 | D28: Short_Form_Blueprint

Sheet Instructions
A1: NeuroPi Grade 8–12 Student Development Intelligence Programme - Assessment System
A4: Purpose | B4: Structured Grade 8–12 NeuroPi psychometric test across RIASEC, Big Five, Cognitive and Emotional layers, plus learning style, motivation, study habits, career clarity and validity.
A5: How to use | B5: Review Question_Bank. Enter one student’s responses in Student_Responses column M. Score_Summary, Dashboard and Report_Summary calculate automatically.
A6: Likert scoring | B6: 1=Strongly Disagree/Dislike, 2=Disagree, 3=Neutral, 4=Agree, 5=Strongly Agree/Like.
A7: Cognitive scoring | B7: For MCQs, enter A/B/C/D. Correct=1, incorrect=0.
A8: Ethics | B8: Developmental guidance only; not diagnosis, not labeling, not deterministic.
A9: Recommended use | B9: Administer a short form for pilots; use full 525 item bank for adaptive item selection or platform build.
A11: THIS SCORING SYSTEM INCLUDES
A12: 526 categorized questions
A14: RIASEC, Big Five, Cognitive, Emotional layers
A15: RIASEC, Big Five, Cognitive, Emotional layers
A16: Answer key
A17: Student response entry
A18: Automated score summary
A19: Dashboard
A20: Report summary logic
A21: Short-form/adaptive test blueprint
A23: RIASEC
A24: R – Realistic (Doers) | B24: Traits: * Practical * Hands-on * Likes working with tools, machines | C24: Careers: * Engineer * Technician * Pilot * Mechanic
A25: I – Investigative (Thinkers) | B25: Traits: * Analytical * Curious * Problem-solver | C25: Careers: * Scientist * Doctor * Data analyst * Researcher
A26: A – Artistic (Creators) | B26: Traits: * Creative * Expressive * Imaginative | C26: Careers: * Designer * Writer * Musician * Actor
A27: S – Social (Helpers) | B27: Traits: * Empathetic * Supportive * Likes helping people | C27: Careers: * Teacher * Counselor * Psychologist * Nurse
A28: E – Enterprising (Leaders) | B28: Traits: * Confident * Persuasive * Leadership-oriented | C28: Careers: * Entrepreneur * Manager * Lawyer * Sales leader
A29: C – Conventional (Organizers) | B29: Traits: * Organized * Detail-oriented * Structured | C29: Careers: * Accountant * Banker * Administrator * Data manager
A31: Big Five Traits (OCEAN) = 5 Core Traits
A32: O – Openness to Experience | B32: What it means: Curiosity, imagination, creativity Openness to new ideas and experiences | C32: High Openness: Creative, imaginative, curious | D32: Low Openness: Practical, prefers routine, traditional
A33: C – Conscientiousness | B33: What it means: Discipline, organization, responsibility | C33: High Conscientiousness: Structured, reliable, goal-oriented | D33: Low Conscientiousness: Disorganized, inconsistent, impulsive
A34: E – Extraversion | B34: What it means: Energy from social interaction | C34: High Extraversion: Outgoing, talkative, energetic | D34: Low Extraversion (Introversion): Quiet, reflective, prefers solitude
A35: A – Agreeableness | B35: What it means: Kindness, empathy, cooperation | C35: High Agreeableness: Supportive, compassionate | D35: Low Agreeableness: Competitive, direct, less emotionally expressive
A36: N – Neuroticism (Emotional Stability) | B36: What it means: Kindness, empathy, cooperation | C36: High Agreeableness: Supportive, compassionate | D36: Low Agreeableness: Competitive, direct, less emotionally expressive

Sheet Scoring_Map
A1: Scoring Map
A2: Interpretation bands and counselor actions
A4: Domain | B4: Subdomain | C4: Low Interpretation | D4: Moderate Interpretation | E4: High Interpretation | F4: Counselor Action
A5: RIASEC | B5: R | C5: Practical exposure needed before hands-on pathways are recommended. | D5: Balanced interest in practical activities. | E5: Strong practical, hands-on interest. | F5: Offer lab, robotics, field and technical exposure.
A6: RIASEC | B6: I | C6: Needs guided curiosity-building. | D6: Moderate analytical interest. | E6: Strong science/research/problem-solving interest. | F6: Offer STEM, research, data and inquiry-based pathways.
A7: RIASEC | B7: A | C7: Creative interests not currently dominant. | D7: Some creative expression. | E7: Strong creative and expressive interests. | F7: Offer design, media, writing and portfolio options.
A8: RIASEC | B8: S | C8: May prefer independent work. | D8: Balanced people orientation. | E8: Strong helping, teaching and mentoring orientation. | F8: Offer psychology, teaching, healthcare and social impact exposure.
A9: RIASEC | B9: E | C9: May prefer non-leadership roles initially. | D9: Some leadership potential. | E9: Strong enterprise and influence orientation. | F9: Offer entrepreneurship, management, law and public speaking.
A10: RIASEC | B10: C | C10: May resist routine. | D10: Can work with structure. | E10: Strong organizing and process orientation. | F10: Offer finance, operations, analytics and administration exposure.
A11: Big Five | B11: Openness | C11: Prefers familiar methods. | D11: Balanced curiosity and practicality. | E11: Curious, imaginative and open to new ideas. | F11: Use exploratory projects and innovation tasks.
A12: Big Five | B12: Conscientiousness | C12: Needs routines and accountability. | D12: Consistent with support. | E12: Organized and reliable. | F12: Use structured plans and deadlines.
A13: Big Five | B13: Extraversion | C13: Prefers quiet independent work. | D13: Comfortable alone and in groups. | E13: Energized by interaction. | F13: Use group work, presentations and mentoring roles.
A14: Big Five | B14: Agreeableness | C14: May be direct or competitive. | D14: Balanced cooperation. | E14: Empathetic and supportive. | F14: Use teamwork and peer-support roles.
A15: Big Five | B15: Neuroticism | C15: Emotionally steady under pressure. | D15: Some stress sensitivity. | E15: High stress sensitivity; pressure may affect performance. | F15: Recommend emotional safety and stress strategies.
... A32: Validity | B32: Validity | C32: Response consistency needs review. | D32: Generally usable pattern. | E32: Strong consistency. | F32: If low, re-administer or interview student.

Sheet Question_Bank
A1: NeuroPi Question Bank — Grade 8 to Grade 12
A2: 525 categorized items for platform build, adaptive tests or school deployment
A4: QID | B4: Grade Band | C4: Domain | D4: Subdomain | E4: Trait/Code | F4: Question Type | G4: Question | H4: Option A | I4: Option B | J4: Option C | K4: Option D | L4: Correct/Key | M4: Scale / Scoring | N4: Reverse Scored | O4: Difficulty | P4: Report Tag | Q4: Counselor Note
A5: NPI0001 | B5: 8-12 | C5: RIASEC Interest | D5: Realistic | E5: R | F5: Likert | G5: I enjoy activities involving building or fixing things. | M5: 1-5 Likert: 1=Strongly Disagree/Dislike, 5=Strongly Agree/Like | N5: No | O5: Easy | P5: Realistic Interest | Q5: Higher response increases interest score.
A6: NPI0002 | B6: 8-12 | C6: RIASEC Interest | D6: Realistic | E6: R | F6: Likert | G6: I enjoy activities involving using tools or equipment. | M6: 1-5 Likert: 1=Strongly Disagree/Dislike, 5=Strongly Agree/Like | N6: No | O6: Easy | P6: Realistic Interest | Q6: Higher response increases interest score.
A7: NPI0003 | B7: 8-12 | C7: RIASEC Interest | D7: Realistic | E7: R | F7: Likert | G7: I enjoy activities involving robotics or electronics. | M7: 1-5 Likert: 1=Strongly Disagree/Dislike, 5=Strongly Agree/Like | N7: No | O7: Easy | P7: Realistic Interest | Q7: Higher response increases interest score.
A8: NPI0004 | B8: 8-12 | C8: RIASEC Interest | D8: Realistic | E8: R | F8: Likert | G8: I enjoy activities involving field activities. | M8: 1-5 Likert: 1=Strongly Disagree/Dislike, 5=Strongly Agree/Like | N8: No | O8: Easy | P8: Realistic Interest | Q8: Higher response increases interest score.
A9: NPI0005 | B9: 8-12 | C9: RIASEC Interest | D9: Realistic | E9: R | F9: Likert | G9: I enjoy activities involving technical workshops. | M9: 1-5 Likert: 1=Strongly Disagree/Dislike, 5=Strongly Agree/Like | N9: No | O9: Easy | P9: Realistic Interest | Q9: Higher response increases interest score.
A10: NPI0006 | B10: 8-12 | C10: RIASEC Interest | D10: Realistic | E10: R | F10: Likert | G10: I enjoy activities involving hands-on science labs. | M10: 1-5 Likert: 1=Strongly Disagree/Dislike, 5=Strongly Agree/Like | N10: No | O10: Easy | P10: Realistic Interest | Q10: Higher response increases interest score.
A11: NPI0007 | B11: 8-12 | C11: RIASEC Interest | D11: Realistic | E11: R | F11: Likert | G11: I enjoy activities involving repairing devices. | M11: 1-5 Likert: 1=Strongly Disagree/Dislike, 5=Strongly Agree/Like | N11: No | O11: Easy | P11: Realistic Interest | Q11: Higher response increases interest score.
A12: NPI0008 | B12: 8-12 | C12: RIASEC Interest | D12: Realistic | E12: R | F12: Likert | G12: I enjoy activities involving making useful models. | M12: 1-5 Likert: 1=Strongly Disagree/Dislike, 5=Strongly Agree/Like | N12: No | O12: Easy | P12: Realistic Interest | Q12: Higher response increases interest score.
A13: NPI0009 | B13: 8-12 | C13: RIASEC Interest | D13: Realistic | E13: R | F13: Likert | G13: I enjoy activities involving practical experiments. | M13: 1-5 Likert: 1=Strongly Disagree/Dislike, 5=Strongly Agree/Like | N13: No | O13: Medium | P13: Realistic Interest | Q13: Higher response increases interest score.
A14: NPI0010 | B14: 8-12 | C14: RIASEC Interest | D14: Realistic | E14: R | F14: Likert | G14: I enjoy activities involving engineering activities. | M14: 1-5 Likert: 1=Strongly Disagree/Dislike, 5=Strongly Agree/Like | N14: No | O14: Medium | P14: Realistic Interest | Q14: Higher response increases interest score.
A15: NPI0011 | B15: 8-12 | C15: RIASEC Interest | D15: Realistic | E15: R | F15: Likert | G15: I enjoy activities involving machines and systems. | M15: 1-5 Likert: 1=Strongly Disagree/Dislike, 5=Strongly Agree/Like | N15: No | O15: Medium | P15: Realistic Interest | Q15: Higher response increases interest score.
A16: NPI0012 | B16: 8-12 | C16: RIASEC Interest | D16: Realistic | E16: R | F16: Likert | G16: I enjoy activities involving outdoor problem-solving. | M16: 1-5 Likert: 1=Strongly Disagree/Dislike, 5=Strongly Agree/Like | N16: No | O16: Medium | P16: Realistic Interest | Q16: Higher response increases interest score.
... A219: NPI0215 | B219: 8-12 | C219: Big Five Personality | D219: Neuroticism | E219: Neuroticism | F219: Likert | G219: I calm myself when stressed. | M219: 1-5 Likert: 1=Strongly Disagree/Dislike, 5=Strongly Agree/Like | N219: Yes | O219: Medium | P219: Neuroticism Trait | Q219: Reverse scored: score = 6-response.
A220: NPI0216 | B220: 8-12 | C220: Cognitive Ability | D220: Numerical | E220: Numerical | F220: MCQ | G220: What comes next: 3, 6, 9, 12, ? | H220: 13 | I220: 14 | J220: 15 | K220: 18 | L220: C | M220: MCQ: correct=1, incorrect=0 | N220: No | O220: Medium | P220: Numerical Reasoning | Q220: Use accuracy and response time where platform allows.
A221: NPI0217 | B221: 8-12 | C221: Cognitive Ability | D221: Numerical | E221: Numerical | F221: MCQ | G221: If 5 notebooks cost ₹150, one costs: | H221: ₹20 | I221: ₹25 | J221: ₹30 | K221: ₹35 | L221: C | M221: MCQ: correct=1, incorrect=0 | N221: No | O221: Medium | P221: Numerical Reasoning | Q221: Use accuracy and response time where platform allows.
A222: NPI0218 | B222: 8-12 | C222: Cognitive Ability | D222: Numerical | E222: Numerical | F222: MCQ | G222: What is 20% of 250? | H222: 25 | I222: 40 | J222: 50 | K222: 60 | L222: C | M222: MCQ: correct=1, incorrect=0 | N222: No | O222: Medium | P222: Numerical Reasoning | Q222: Use accuracy and response time where platform allows.
A223: NPI0219 | B223: 8-12 | C223: Cognitive Ability | D223: Numerical | E223: Numerical | F223: MCQ | G223: Speed: 180 km in 3 hours = | H223: 40 | I223: 50 | J223: 60 | K223: 70 | L223: C | M223: MCQ: correct=1, incorrect=0 | N223: No | O223: Medium | P223: Numerical Reasoning | Q223: Use accuracy and response time where platform allows.
A224: NPI0220 | B224: 8-12 | C224: Cognitive Ability | D224: Numerical | E224: Numerical | F224: MCQ | G224: 2,4,8,16,? | H224: 24 | I224: 28 | J224: 32 | K224: 36 | L224: C | M224: MCQ: correct=1, incorrect=0 | N224: No | O224: Medium | P224: Numerical Reasoning | Q224: Use accuracy and response time where platform allows.
A225: NPI0221 | B225: 8-12 | C225: Cognitive Ability | D225: Numerical | E225: Numerical | F225: MCQ | G225: x+7=19, x= | H225: 10 | I225: 11 | J225: 12 | K225: 13 | L225: C | M225: MCQ: correct=1, incorrect=0 | N225: No | O225: Medium | P225: Numerical Reasoning | Q225: Use accuracy and response time where platform allows.
A226: NPI0222 | B226: 8-12 | C226: Cognitive Ability | D226: Numerical | E226: Numerical | F226: MCQ | G226: Average of 8,10,12,14 | H226: 10 | I226: 11 | J226: 12 | K226: 13 | L226: B | M226: MCQ: correct=1, incorrect=0 | N226: No | O226: Medium | P226: Numerical Reasoning | Q226: Use accuracy and response time where platform allows.
A227: NPI0223 | B227: 8-12 | C227: Cognitive Ability | D227: Numerical | E227: Numerical | F227: MCQ | G227: Ratio 2:3 total 25, first part | H227: 8 | I227: 10 | J227: 12 | K227: 15 | L227: B | M227: MCQ: correct=1, incorrect=0 | N227: No | O227: Medium | P227: Numerical Reasoning | Q227: Use accuracy and response time where platform allows.
A228: NPI0224 | B228: 8-12 | C228: Cognitive Ability | D228: Numerical | E228: Numerical | F228: MCQ | G228: 15 × 6 | H228: 80 | I228: 85 | J228: 90 | K228: 95 | L228: C | M228: MCQ: correct=1, incorrect=0 | N228: No | O228: Medium | P228: Numerical Reasoning | Q228: Use accuracy and response time where platform allows.
A229: NPI0225 | B229: 8-12 | C229: Cognitive Ability | D229: Numerical | E229: Numerical | F229: MCQ | G229: 10% discount on ₹800 final price | H229: ₹700 | I229: ₹720 | J229: ₹760 | K229: ₹780 | L229: B | M229: MCQ: correct=1, incorrect=0 | N229: No | O229: Medium | P229: Numerical Reasoning | Q229: Use accuracy and response time where platform allows.
A230: NPI0226 | B230: 8-12 | C230: Cognitive Ability | D230: Numerical | E230: Numerical | F230: MCQ | G230: 5,10,20,40,? | H230: 60 | I230: 70 | J230: 80 | K230: 100 | L230: C | M230: MCQ: correct=1, incorrect=0 | N230: No | O230: Medium | P230: Numerical Reasoning | Q230: Use accuracy and response time where platform allows.
A231: NPI0227 | B231: 8-12 | C231: Cognitive Ability | D231: Numerical | E231: Numerical | F231: MCQ | G231: 3/4 of number is 60, number | H231: 75 | I231: 80 | J231: 90 | K231: 100 | L231: B | M231: MCQ: correct=1, incorrect=0 | N231: No | O231: Medium | P231: Numerical Reasoning | Q231: Use accuracy and response time where platform allows.
... A319: NPI0315 | B319: 8-12 | C319: Cognitive Ability | D319: Spatial | E319: Spatial | F319: MCQ | G319: Longest: 5cm,50mm,0.6m,20cm | H319: 5cm | I319: 50mm | J319: 0.6m | K319: 20cm | L319: C | M319: MCQ: correct=1, incorrect=0 | N319: No | O319: Medium | P319: Spatial Reasoning | Q319: Use accuracy and response time where platform allows.
A320: NPI0316 | B320: 8-12 | C320: Emotional Profile | D320: Stress | E320: Stress | F320: Likert | G320: I feel tense before exams. | M320: 1-5 Likert: 1=Strongly Disagree/Dislike, 5=Strongly Agree/Like | N320: No | O320: Medium | P320: Stress Indicator | Q320: Interpret with student interview and context.
A321: NPI0317 | B321: 8-12 | C321: Emotional Profile | D321: Stress | E321: Stress | F321: Likert | G321: I feel overwhelmed by workload. | M321: 1-5 Likert: 1=Strongly Disagree/Dislike, 5=Strongly Agree/Like | N321: No | O321: Medium | P321: Stress Indicator | Q321: Interpret with student interview and context.
A322: NPI0318 | B322: 8-12 | C322: Emotional Profile | D322: Stress | E322: Stress | F322: Likert | G322: I worry about marks after studying. | M322: 1-5 Likert: 1=Strongly Disagree/Dislike, 5=Strongly Agree/Like | N322: No | O322: Medium | P322: Stress Indicator | Q322: Interpret with student interview and context.
A323: NPI0319 | B323: 8-12 | C323: Emotional Profile | D323: Stress | E323: Stress | F323: Likert | G323: I feel pressure from expectations. | M323: 1-5 Likert: 1=Strongly Disagree/Dislike, 5=Strongly Agree/Like | N323: No | O323: Medium | P323: Stress Indicator | Q323: Interpret with student interview and context.
A324: NPI0320 | B324: 8-12 | C324: Emotional Profile | D324: Stress | E324: Stress | F324: Likert | G324: I compare myself with others nervously. | M324: 1-5 Likert: 1=Strongly Disagree/Dislike, 5=Strongly Agree/Like | N324: No | O324: Medium | P324: Stress Indicator | Q324: Interpret with student interview and context.
A325: NPI0321 | B325: 8-12 | C325: Emotional Profile | D325: Stress | E325: Stress | F325: Likert | G325: I feel stress in competition. | M325: 1-5 Likert: 1=Strongly Disagree/Dislike, 5=Strongly Agree/Like | N325: No | O325: Medium | P325: Stress Indicator | Q325: Interpret with student interview and context.
A326: NPI0322 | B326: 8-12 | C326: Emotional Profile | D326: Stress | E326: Stress | F326: Likert | G326: I fear disappointing people. | M326: 1-5 Likert: 1=Strongly Disagree/Dislike, 5=Strongly Agree/Like | N326: No | O326: Medium | P326: Stress Indicator | Q326: Interpret with student interview and context.
A327: NPI0323 | B327: 8-12 | C327: Emotional Profile | D327: Stress | E327: Stress | F327: Likert | G327: I panic when I do not know an answer. | M327: 1-5 Likert: 1=Strongly Disagree/Dislike, 5=Strongly Agree/Like | N327: No | O327: Medium | P327: Stress Indicator | Q327: Interpret with student interview and context.
A328: NPI0324 | B328: 8-12 | C328: Emotional Profile | D328: Stress | E328: Stress | F328: Likert | G328: I overthink after mistakes. | M328: 1-5 Likert: 1=Strongly Disagree/Dislike, 5=Strongly Agree/Like | N328: No | O328: Medium | P328: Stress Indicator | Q328: Interpret with student interview and context.
A329: NPI0325 | B329: 8-12 | C329: Emotional Profile | D329: Stress | E329: Stress | F329: Likert | G329: I feel pressure to be perfect. | M329: 1-5 Likert: 1=Strongly Disagree/Dislike, 5=Strongly Agree/Like | N329: No | O329: Medium | P329: Stress Indicator | Q329: Interpret with student interview and context.
A330: NPI0326 | B330: 8-12 | C330: Emotional Profile | D330: Stress | E330: Stress | F330: Likert | G330: I feel drained after long study. | M330: 1-5 Likert: 1=Strongly Disagree/Dislike, 5=Strongly Agree/Like | N330: No | O330: Medium | P330: Stress Indicator | Q330: Interpret with student interview and context.
...

Sheet Student_Responses
A1: Student Response Entry
A2: Enter responses in column M only
A4: Student Name
A5: Grade
A6: School
A7: Assessment Date
A8: Counselor
A11: QID | B11: Grade Band | C11: Domain | D11: Subdomain | E11: Trait/Code | F11: Question Type | G11: Question | H11: Option A | I11: Option B | J11: Option C | K11: Option D | L11: Correct/Key | M11: Student Response | N11: Score | O11: Reverse | P11: Max Score
A12: {='Question_Bank'!A4} -> QID | B12: {='Question_Bank'!B4} -> Grade Band | C12: {='Question_Bank'!C4} -> Domain | D12: {='Question_Bank'!D4} -> Subdomain | E12: {='Question_Bank'!E4} -> Trait/Code | F12: {='Question_Bank'!F4} -> Question Type | G12: {='Question_Bank'!G4} -> Question | H12: {='Question_Bank'!H4} -> Option A | ... L12: {='Question_Bank'!L4} -> Correct/Key | N12: {=IF(M12="","",IF(F12="MCQ",IF(UPPER(M12)=UPPER(L12),1,0),IF(O12="Yes",6-VALUE(M12),VALUE(M12))))} | O12: {='Question_Bank'!N4} -> Reverse Scored | P12: {=IF(F12="MCQ",1,5)} -> 5
A13: {='Question_Bank'!A5} -> NPI0001 | B13: {='Question_Bank'!B5} -> 8-12 | C13: {='Question_Bank'!C5} -> RIASEC Interest | D13: {='Question_Bank'!D5} -> Realistic | E13: {='Question_Bank'!E5} -> R | F13: {='Question_Bank'!F5} -> Likert | G13: {='Question_Bank'!G5} -> I enjoy activities involving building or fixing things. | H13: {='Question_Bank'!H5} -> 0 | ... L13: {='Question_Bank'!L5} -> 0 | N13: {=IF(M13="","",IF(F13="MCQ",IF(UPPER(M13)=UPPER(L13),1,0),IF(O13="Yes",6-VALUE(M13),VALUE(M13))))} | O13: {='Question_Bank'!N5} -> No | P13: {=IF(F13="MCQ",1,5)} -> 5
A14: {='Question_Bank'!A6} -> NPI0002 | B14: {='Question_Bank'!B6} -> 8-12 | C14: {='Question_Bank'!C6} -> RIASEC Interest | D14: {='Question_Bank'!D6} -> Realistic | E14: {='Question_Bank'!E6} -> R | F14: {='Question_Bank'!F6} -> Likert | G14: {='Question_Bank'!G6} -> I enjoy activities involving using tools or equipment. | H14: {='Question_Bank'!H6} -> 0 | ... L14: {='Question_Bank'!L6} -> 0 | N14: {=IF(M14="","",IF(F14="MCQ",IF(UPPER(M14)=UPPER(L14),1,0),IF(O14="Yes",6-VALUE(M14),VALUE(M14))))} | O14: {='Question_Bank'!N6} -> No | P14: {=IF(F14="MCQ",1,5)} -> 5
A15: {='Question_Bank'!A7} -> NPI0003 | B15: {='Question_Bank'!B7} -> 8-12 | C15: {='Question_Bank'!C7} -> RIASEC Interest | D15: {='Question_Bank'!D7} -> Realistic | E15: {='Question_Bank'!E7} -> R | F15: {='Question_Bank'!F7} -> Likert | G15: {='Question_Bank'!G7} -> I enjoy activities involving robotics or electronics. | H15: {='Question_Bank'!H7} -> 0 | ... L15: {='Question_Bank'!L7} -> 0 | N15: {=IF(M15="","",IF(F15="MCQ",IF(UPPER(M15)=UPPER(L15),1,0),IF(O15="Yes",6-VALUE(M15),VALUE(M15))))} | O15: {='Question_Bank'!N7} -> No | P15: {=IF(F15="MCQ",1,5)} -> 5
A16: {='Question_Bank'!A8} -> NPI0004 | B16: {='Question_Bank'!B8} -> 8-12 | C16: {='Question_Bank'!C8} -> RIASEC Interest | D16: {='Question_Bank'!D8} -> Realistic | E16: {='Question_Bank'!E8} -> R | F16: {='Question_Bank'!F8} -> Likert | G16: {='Question_Bank'!G8} -> I enjoy activities involving field activities. | H16: {='Question_Bank'!H8} -> 0 | ... L16: {='Question_Bank'!L8} -> 0 | N16: {=IF(M16="","",IF(F16="MCQ",IF(UPPER(M16)=UPPER(L16),1,0),IF(O16="Yes",6-VALUE(M16),VALUE(M16))))} | O16: {='Question_Bank'!N8} -> No | P16: {=IF(F16="MCQ",1,5)} -> 5
A17: {='Question_Bank'!A9} -> NPI0005 | B17: {='Question_Bank'!B9} -> 8-12 | C17: {='Question_Bank'!C9} -> RIASEC Interest | D17: {='Question_Bank'!D9} -> Realistic | E17: {='Question_Bank'!E9} -> R | F17: {='Question_Bank'!F9} -> Likert | G17: {='Question_Bank'!G9} -> I enjoy activities involving technical workshops. | H17: {='Question_Bank'!H9} -> 0 | ... L17: {='Question_Bank'!L9} -> 0 | N17: {=IF(M17="","",IF(F17="MCQ",IF(UPPER(M17)=UPPER(L17),1,0),IF(O17="Yes",6-VALUE(M17),VALUE(M17))))} | O17: {='Question_Bank'!N9} -> No | P17: {=IF(F17="MCQ",1,5)} -> 5
A18: {='Question_Bank'!A10} -> NPI0006 | B18: {='Question_Bank'!B10} -> 8-12 | C18: {='Question_Bank'!C10} -> RIASEC Interest | D18: {='Question_Bank'!D10} -> Realistic | E18: {='Question_Bank'!E10} -> R | F18: {='Question_Bank'!F10} -> Likert | G18: {='Question_Bank'!G10} -> I enjoy activities involving hands-on science labs. | H18: {='Question_Bank'!H10} -> 0 | ... L18: {='Question_Bank'!L10} -> 0 | N18: {=IF(M18="","",IF(F18="MCQ",IF(UPPER(M18)=UPPER(L18),1,0),IF(O18="Yes",6-VALUE(M18),VALUE(M18))))} | O18: {='Question_Bank'!N10} -> No | P18: {=IF(F18="MCQ",1,5)} -> 5
A19: {='Question_Bank'!A11} -> NPI0007 | B19: {='Question_Bank'!B11} -> 8-12 | C19: {='Question_Bank'!C11} -> RIASEC Interest | D19: {='Question_Bank'!D11} -> Realistic | E19: {='Question_Bank'!E11} -> R | F19: {='Question_Bank'!F11} -> Likert | G19: {='Question_Bank'!G11} -> I enjoy activities involving repairing devices. | H19: {='Question_Bank'!H11} -> 0 | ... L19: {='Question_Bank'!L11} -> 0 | N19: {=IF(M19="","",IF(F19="MCQ",IF(UPPER(M19)=UPPER(L19),1,0),IF(O19="Yes",6-VALUE(M19),VALUE(M19))))} | O19: {='Question_Bank'!N11} -> No | P19: {=IF(F19="MCQ",1,5)} -> 5
A20: {='Question_Bank'!A12} -> NPI0008 | B20: {='Question_Bank'!B12} -> 8-12 | C20: {='Question_Bank'!C12} -> RIASEC Interest | D20: {='Question_Bank'!D12} -> Realistic | E20: {='Question_Bank'!E12} -> R | F20: {='Question_Bank'!F12} -> Likert | G20: {='Question_Bank'!G12} -> I enjoy activities involving making useful models. | H20: {='Question_Bank'!H12} -> 0 | ... L20: {='Question_Bank'!L12} -> 0 | N20: {=IF(M20="","",IF(F20="MCQ",IF(UPPER(M20)=UPPER(L20),1,0),IF(O20="Yes",6-VALUE(M20),VALUE(M20))))} | O20: {='Question_Bank'!N12} -> No | P20: {=IF(F20="MCQ",1,5)} -> 5
A21: {='Question_Bank'!A13} -> NPI0009 | B21: {='Question_Bank'!B13} -> 8-12 | C21: {='Question_Bank'!C13} -> RIASEC Interest | D21: {='Question_Bank'!D13} -> Realistic | E21: {='Question_Bank'!E13} -> R | F21: {='Question_Bank'!F13} -> Likert | G21: {='Question_Bank'!G13} -> I enjoy activities involving practical experiments. | H21: {='Question_Bank'!H13} -> 0 | ... L21: {='Question_Bank'!L13} -> 0 | N21: {=IF(M21="","",IF(F21="MCQ",IF(UPPER(M21)=UPPER(L21),1,0),IF(O21="Yes",6-VALUE(M21),VALUE(M21))))} | O21: {='Question_Bank'!N13} -> No | P21: {=IF(F21="MCQ",1,5)} -> 5
A22: {='Question_Bank'!A14} -> NPI0010 | B22: {='Question_Bank'!B14} -> 8-12 | C22: {='Question_Bank'!C14} -> RIASEC Interest | D22: {='Question_Bank'!D14} -> Realistic | E22: {='Question_Bank'!E14} -> R | F22: {='Question_Bank'!F14} -> Likert | G22: {='Question_Bank'!G14} -> I enjoy activities involving engineering activities. | H22: {='Question_Bank'!H14} -> 0 | ... L22: {='Question_Bank'!L14} -> 0 | N22: {=IF(M22="","",IF(F22="MCQ",IF(UPPER(M22)=UPPER(L22),1,0),IF(O22="Yes",6-VALUE(M22),VALUE(M22))))} | O22: {='Question_Bank'!N14} -> No | P22: {=IF(F22="MCQ",1,5)} -> 5
A23: {='Question_Bank'!A15} -> NPI0011 | B23: {='Question_Bank'!B15} -> 8-12 | C23: {='Question_Bank'!C15} -> RIASEC Interest | D23: {='Question_Bank'!D15} -> Realistic | E23: {='Question_Bank'!E15} -> R | F23: {='Question_Bank'!F15} -> Likert | G23: {='Question_Bank'!G15} -> I enjoy activities involving machines and systems. | H23: {='Question_Bank'!H15} -> 0 | ... L23: {='Question_Bank'!L15} -> 0 | N23: {=IF(M23="","",IF(F23="MCQ",IF(UPPER(M23)=UPPER(L23),1,0),IF(O23="Yes",6-VALUE(M23),VALUE(M23))))} | O23: {='Question_Bank'!N15} -> No | P23: {=IF(F23="MCQ",1,5)} -> 5
... A537: {='Question_Bank'!A529} -> NPI0525 | B537: {='Question_Bank'!B529} -> 8-12 | C537: {='Question_Bank'!C529} -> Validity & Readiness | D537: {='Question_Bank'!D529} -> Validity | E537: {='Question_Bank'!E529} -> Validity | F537: {='Question_Bank'!F529} -> Likert | G537: {='Question_Bank'!G529} -> I would like to discuss my results with a counselor. | H537: {='Question_Bank'!H529} -> 0 | ... L537: {='Question_Bank'!L529} -> 0 | N537: {=IF(M537="","",IF(F537="MCQ",IF(UPPER(M537)=UPPER(L537),1,0),IF(O537="Yes",6-VALUE(M537),VALUE(M537))))} | O537: {='Question_Bank'!N529} -> No | P537: {=IF(F537="MCQ",1,5)} -> 5

Sheet Score_Summary
A1: Automated Score Summary
A2: Formula-driven summary from Student_Responses
A4: Domain | B4: Subdomain | C4: Raw Score | D4: Max Score | E4: Score % | F4: Band | G4: Interpretation
A5: RIASEC Interest | B5: R | C5: {=_xlfn.SUMIFS('Student_Responses'!$N1:$N537,'Student_Responses'!$E1:$E537,B5,'Student_Responses'!$C1:$C537,A5)} -> 0 | D5: {=_xlfn.SUMIFS('Student_Responses'!$P1:$P537,'Student_Responses'!$E1:$E537,B5,'Student_Responses'!$C1:$C537,A5)} -> 75 | E5: {=IF(D5=0,"",C5/D5)} -> 0 | F5: {=IF(E5="","",IF(E5<0.4,"Low",IF(E5<0.7,"Moderate","High")))} -> Low | G5: Practical exposure needed before hands-on pathways are recommended.
A6: RIASEC Interest | B6: I | C6: {=_xlfn.SUMIFS('Student_Responses'!$N1:$N537,'Student_Responses'!$E1:$E537,B6,'Student_Responses'!$C1:$C537,A6)} -> 0 | D6: {=_xlfn.SUMIFS('Student_Responses'!$P1:$P537,'Student_Responses'!$E1:$E537,B6,'Student_Responses'!$C1:$C537,A6)} -> 75 | E6: {=IF(D6=0,"",C6/D6)} -> 0 | F6: {=IF(E6="","",IF(E6<0.4,"Low",IF(E6<0.7,"Moderate","High")))} -> Low | G6: Needs guided curiosity-building.
A7: RIASEC Interest | B7: A | C7: {=_xlfn.SUMIFS('Student_Responses'!$N1:$N537,'Student_Responses'!$E1:$E537,B7,'Student_Responses'!$C1:$C537,A7)} -> 0 | D7: {=_xlfn.SUMIFS('Student_Responses'!$P1:$P537,'Student_Responses'!$E1:$E537,B7,'Student_Responses'!$C1:$C537,A7)} -> 75 | E7: {=IF(D7=0,"",C7/D7)} -> 0 | F7: {=IF(E7="","",IF(E7<0.4,"Low",IF(E7<0.7,"Moderate","High")))} -> Low | G7: Creative interests not currently dominant.
A8: RIASEC Interest | B8: S | C8: {=_xlfn.SUMIFS('Student_Responses'!$N1:$N537,'Student_Responses'!$E1:$E537,B8,'Student_Responses'!$C1:$C537,A8)} -> 0 | D8: {=_xlfn.SUMIFS('Student_Responses'!$P1:$P537,'Student_Responses'!$E1:$E537,B8,'Student_Responses'!$C1:$C537,A8)} -> 75 | E8: {=IF(D8=0,"",C8/D8)} -> 0 | F8: {=IF(E8="","",IF(E8<0.4,"Low",IF(E8<0.7,"Moderate","High")))} -> Low | G8: May prefer independent work.
A9: RIASEC Interest | B9: E | C9: {=_xlfn.SUMIFS('Student_Responses'!$N1:$N537,'Student_Responses'!$E1:$E537,B9,'Student_Responses'!$C1:$C537,A9)} -> 0 | D9: {=_xlfn.SUMIFS('Student_Responses'!$P1:$P537,'Student_Responses'!$E1:$E537,B9,'Student_Responses'!$C1:$C537,A9)} -> 75 | E9: {=IF(D9=0,"",C9/D9)} -> 0 | F9: {=IF(E9="","",IF(E9<0.4,"Low",IF(E9<0.7,"Moderate","High")))} -> Low | G9: May prefer non-leadership roles initially.
A10: RIASEC Interest | B10: C | C10: {=_xlfn.SUMIFS('Student_Responses'!$N1:$N537,'Student_Responses'!$E1:$E537,B10,'Student_Responses'!$C1:$C537,A10)} -> 0 | D10: {=_xlfn.SUMIFS('Student_Responses'!$P1:$P537,'Student_Responses'!$E1:$E537,B10,'Student_Responses'!$C1:$C537,A10)} -> 75 | E10: {=IF(D10=0,"",C10/D10)} -> 0 | F10: {=IF(E10="","",IF(E10<0.4,"Low",IF(E10<0.7,"Moderate","High")))} -> Low | G10: May resist routine.
A11: Big Five Personality | B11: Openness | C11: {=_xlfn.SUMIFS('Student_Responses'!$N1:$N537,'Student_Responses'!$E1:$E537,B11,'Student_Responses'!$C1:$C537,A11)} -> 0 | D11: {=_xlfn.SUMIFS('Student_Responses'!$P1:$P537,'Student_Responses'!$E1:$E537,B11,'Student_Responses'!$C1:$C537,A11)} -> 125 | E11: {=IF(D11=0,"",C11/D11)} -> 0 | F11: {=IF(E11="","",IF(E11<0.4,"Low",IF(E11<0.7,"Moderate","High")))} -> Low | G11: Prefers familiar methods.
A12: Big Five Personality | B12: Conscientiousness | C12: {=_xlfn.SUMIFS('Student_Responses'!$N1:$N537,'Student_Responses'!$E1:$E537,B12,'Student_Responses'!$C1:$C537,A12)} -> 0 | D12: {=_xlfn.SUMIFS('Student_Responses'!$P1:$P537,'Student_Responses'!$E1:$E537,B12,'Student_Responses'!$C1:$C537,A12)} -> 125 | E12: {=IF(D12=0,"",C12/D12)} -> 0 | F12: {=IF(E12="","",IF(E12<0.4,"Low",IF(E12<0.7,"Moderate","High")))} -> Low | G12: Needs routines and accountability.
A13: Big Five Personality | B13: Extraversion | C13: {=_xlfn.SUMIFS('Student_Responses'!$N1:$N537,'Student_Responses'!$E1:$E537,B13,'Student_Responses'!$C1:$C537,A13)} -> 0 | D13: {=_xlfn.SUMIFS('Student_Responses'!$P1:$P537,'Student_Responses'!$E1:$E537,B13,'Student_Responses'!$C1:$C537,A13)} -> 125 | E13: {=IF(D13=0,"",C13/D13)} -> 0 | F13: {=IF(E13="","",IF(E13<0.4,"Low",IF(E13<0.7,"Moderate","High")))} -> Low | G13: Prefers quiet independent work.
A14: Big Five Personality | B14: Agreeableness | C14: {=_xlfn.SUMIFS('Student_Responses'!$N1:$N537,'Student_Responses'!$E1:$E537,B14,'Student_Responses'!$C1:$C537,A14)} -> 0 | D14: {=_xlfn.SUMIFS('Student_Responses'!$P1:$P537,'Student_Responses'!$E1:$E537,B14,'Student_Responses'!$C1:$C537,A14)} -> 125 | E14: {=IF(D14=0,"",C14/D14)} -> 0 | F14: {=IF(E14="","",IF(E14<0.4,"Low",IF(E14<0.7,"Moderate","High")))} -> Low | G14: May be direct or competitive.
A15: Big Five Personality | B15: Neuroticism | C15: {=_xlfn.SUMIFS('Student_Responses'!$N1:$N537,'Student_Responses'!$E1:$E537,B15,'Student_Responses'!$C1:$C537,A15)} -> 0 | D15: {=_xlfn.SUMIFS('Student_Responses'!$P1:$P537,'Student_Responses'!$E1:$E537,B15,'Student_Responses'!$C1:$C537,A15)} -> 125 | E15: {=IF(D15=0,"",C15/D15)} -> 0 | F15: {=IF(E15="","",IF(E15<0.4,"Low",IF(E15<0.7,"Moderate","High")))} -> Low | G15: Emotionally steady under pressure.
A16: Cognitive Ability | B16: Logic | C16: {=_xlfn.SUMIFS('Student_Responses'!$N1:$N537,'Student_Responses'!$E1:$E537,B16,'Student_Responses'!$C1:$C537,A16)} -> 0 | D16: {=_xlfn.SUMIFS('Student_Responses'!$P1:$P537,'Student_Responses'!$E1:$E537,B16,'Student_Responses'!$C1:$C537,A16)} -> 20 | E16: {=IF(D16=0,"",C16/D16)} -> 0 | F16: {=IF(E16="","",IF(E16<0.4,"Low",IF(E16<0.7,"Moderate","High")))} -> Low | G16: Needs step-by-step reasoning support.
A17: Cognitive Ability | B17: Numerical | C17: {=_xlfn.SUMIFS('Student_Responses'!$N1:$N537,'Student_Responses'!$E1:$E537,B17,'Student_Responses'!$C1:$C537,A17)} -> 0 | D17: {=_xlfn.SUMIFS('Student_Responses'!$P1:$P537,'Student_Responses'!$E1:$E537,B17,'Student_Responses'!$C1:$C537,A17)} -> 20 | E17: {=IF(D17=0,"",C17/D17)} -> 0 | F17: {=IF(E17="","",IF(E17<0.4,"Low",IF(E17<0.7,"Moderate","High")))} -> Low | G17: Needs number confidence practice.
A18: Cognitive Ability | B18: Verbal | C18: {=_xlfn.SUMIFS('Student_Responses'!$N1:$N537,'Student_Responses'!$E1:$E537,B18,'Student_Responses'!$C1:$C537,A18)} -> 0 | D18: {=_xlfn.SUMIFS('Student_Responses'!$P1:$P537,'Student_Responses'!$E1:$E537,B18,'Student_Responses'!$C1:$C537,A18)} -> 20 | E18: {=IF(D18=0,"",C18/D18)} -> 0 | F18: {=IF(E18="","",IF(E18<0.4,"Low",IF(E18<0.7,"Moderate","High")))} -> Low | G18: Needs vocabulary/comprehension support.
A19: Cognitive Ability | B19: Abstract | C19: {=_xlfn.SUMIFS('Student_Responses'!$N1:$N537,'Student_Responses'!$E1:$E537,B19,'Student_Responses'!$C1:$C537,A19)} -> 0 | D19: {=_xlfn.SUMIFS('Student_Responses'!$P1:$P537,'Student_Responses'!$E1:$E537,B19,'Student_Responses'!$C1:$C537,A19)} -> 20 | E19: {=IF(D19=0,"",C19/D19)} -> 0 | F19: {=IF(E19="","",IF(E19<0.4,"Low",IF(E19<0.7,"Moderate","High")))} -> Low | G19: Needs pattern-thinking practice.
A20: Cognitive Ability | B20: Spatial | C20: {=_xlfn.SUMIFS('Student_Responses'!$N1:$N537,'Student_Responses'!$E1:$E537,B20,'Student_Responses'!$C1:$C537,A20)} -> 0 | D20: {=_xlfn.SUMIFS('Student_Responses'!$P1:$P537,'Student_Responses'!$E1:$E537,B20,'Student_Responses'!$C1:$C537,A20)} -> 20 | E20: {=IF(D20=0,"",C20/D20)} -> 0 | F20: {=IF(E20="","",IF(E20<0.4,"Low",IF(E20<0.7,"Moderate","High")))} -> Low | G20: Needs visual-spatial practice.
A21: Emotional Profile | B21: Stress | C21: {=_xlfn.SUMIFS('Student_Responses'!$N1:$N537,'Student_Responses'!$E1:$E537,B21,'Student_Responses'!$C1:$C537,A21)} -> 0 | D21: {=_xlfn.SUMIFS('Student_Responses'!$P1:$P537,'Student_Responses'!$E1:$E537,B21,'Student_Responses'!$C1:$C537,A21)} -> 100 | E21: {=IF(D21=0,"",C21/D21)} -> 0 | F21: {=IF(E21="","",IF(E21<0.4,"Low",IF(E21<0.7,"Moderate","High")))} -> Low | G21: Low reported stress.
A22: Emotional Profile | B22: Confidence | C22: {=_xlfn.SUMIFS('Student_Responses'!$N1:$N537,'Student_Responses'!$E1:$E537,B22,'Student_Responses'!$C1:$C537,A22)} -> 0 | D22: {=_xlfn.SUMIFS('Student_Responses'!$P1:$P537,'Student_Responses'!$E1:$E537,B22,'Student_Responses'!$C1:$C537,A22)} -> 100 | E22: {=IF(D22=0,"",C22/D22)} -> 0 | F22: {=IF(E22="","",IF(E22<0.4,"Low",IF(E22<0.7,"Moderate","High")))} -> Low | G22: Low confidence; may understate ability.
A23: Emotional Profile | B23: Resilience | C23: {=_xlfn.SUMIFS('Student_Responses'!$N1:$N537,'Student_Responses'!$E1:$E537,B23,'Student_Responses'!$C1:$C537,A23)} -> 0 | D23: {=_xlfn.SUMIFS('Student_Responses'!$P1:$P537,'Student_Responses'!$E1:$E537,B23,'Student_Responses'!$C1:$C537,A23)} -> 100 | E23: {=IF(D23=0,"",C23/D23)} -> 0 | F23: {=IF(E23="","",IF(E23<0.4,"Low",IF(E23<0.7,"Moderate","High")))} -> Low | G23: May give up quickly after setbacks.
A24: Emotional Profile | B24: Coping | C24: {=_xlfn.SUMIFS('Student_Responses'!$N1:$N537,'Student_Responses'!$E1:$E537,B24,'Student_Responses'!$C1:$C537,A24)} -> 0 | D24: {=_xlfn.SUMIFS('Student_Responses'!$P1:$P537,'Student_Responses'!$E1:$E537,B24,'Student_Responses'!$C1:$C537,A24)} -> 100 | E24: {=IF(D24=0,"",C24/D24)} -> 0 | F24: {=IF(E24="","",IF(E24<0.4,"Low",IF(E24<0.7,"Moderate","High")))} -> Low | G24: Needs healthier coping strategies.
A25: Learning Style | B25: Visual | C25: {=_xlfn.SUMIFS('Student_Responses'!$N1:$N537,'Student_Responses'!$E1:$E537,B25,'Student_Responses'!$C1:$C537,A25)} -> 0 | D25: {=_xlfn.SUMIFS('Student_Responses'!$P1:$P537,'Student_Responses'!$E1:$E537,B25,'Student_Responses'!$C1:$C537,A25)} -> 75 | E25: {=IF(D25=0,"",C25/D25)} -> 0 | F25: {=IF(E25="","",IF(E25<0.4,"Low",IF(E25<0.7,"Moderate","High")))} -> Low | G25: Visual mode not dominant.
A26: Learning Style | B26: Auditory | C26: {=_xlfn.SUMIFS('Student_Responses'!$N1:$N537,'Student_Responses'!$E1:$E537,B26,'Student_Responses'!$C1:$C537,A26)} -> 0 | D26: {=_xlfn.SUMIFS('Student_Responses'!$P1:$P537,'Student_Responses'!$E1:$E537,B26,'Student_Responses'!$C1:$C537,A26)} -> 75 | E26: {=IF(D26=0,"",C26/D26)} -> 0 | F26: {=IF(E26="","",IF(E26<0.4,"Low",IF(E26<0.7,"Moderate","High")))} -> Low | G26: Listening mode not dominant.
A27: Learning Style | B27: Kinesthetic | C27: {=_xlfn.SUMIFS('Student_Responses'!$N1:$N537,'Student_Responses'!$E1:$E537,B27,'Student_Responses'!$C1:$C537,A27)} -> 0 | D27: {=_xlfn.SUMIFS('Student_Responses'!$P1:$P537,'Student_Responses'!$E1:$E537,B27,'Student_Responses'!$C1:$C537,A27)} -> 75 | E27: {=IF(D27=0,"",C27/D27)} -> 0 | F27: {=IF(E27="","",IF(E27<0.4,"Low",IF(E27<0.7,"Moderate","High")))} -> Low | G27: Hands-on learning not dominant.
A28: Learning Style | B28: ReadingWriting | C28: {=_xlfn.SUMIFS('Student_Responses'!$N1:$N537,'Student_Responses'!$E1:$E537,B28,'Student_Responses'!$C1:$C537,A28)} -> 0 | D28: {=_xlfn.SUMIFS('Student_Responses'!$P1:$P537,'Student_Responses'!$E1:$E537,B28,'Student_Responses'!$C1:$C537,A28)} -> 75 | E28: {=IF(D28=0,"",C28/D28)} -> 0 | F28: {=IF(E28="","",IF(E28<0.4,"Low",IF(E28<0.7,"Moderate","High")))} -> Low | G28: Text mode not dominant.
A29: Additional NeuroPi Indicators | B29: Motivation | C29: {=_xlfn.SUMIFS('Student_Responses'!$N1:$N537,'Student_Responses'!$E1:$E537,B29,'Student_Responses'!$C1:$C537,A29)} -> 0 | D29: {=_xlfn.SUMIFS('Student_Responses'!$P1:$P537,'Student_Responses'!$E1:$E537,B29,'Student_Responses'!$C1:$C537,A29)} -> 100 | E29: {=IF(D29=0,"",C29/D29)} -> 0 | F29: {=IF(E29="","",IF(E29<0.4,"Low",IF(E29<0.7,"Moderate","High")))} -> Low | G29: Needs motivation support.
A30: Additional NeuroPi Indicators | B30: StudyHabits | C30: {=_xlfn.SUMIFS('Student_Responses'!$N1:$N537,'Student_Responses'!$E1:$E537,B30,'Student_Responses'!$C1:$C537,A30)} -> 0 | D30: {=_xlfn.SUMIFS('Student_Responses'!$P1:$P537,'Student_Responses'!$E1:$E537,B30,'Student_Responses'!$C1:$C537,A30)} -> 100 | E30: {=IF(D30=0,"",C30/D30)} -> 0 | F30: {=IF(E30="","",IF(E30<0.4,"Low",IF(E30<0.7,"Moderate","High")))} -> Low | G30: Needs study routine support.
A31: Additional NeuroPi Indicators | B31: CareerClarity | C31: {=_xlfn.SUMIFS('Student_Responses'!$N1:$N537,'Student_Responses'!$E1:$E537,B31,'Student_Responses'!$C1:$C537,A31)} -> 0 | D31: {=_xlfn.SUMIFS('Student_Responses'!$P1:$P537,'Student_Responses'!$E1:$E537,B31,'Student_Responses'!$C1:$C537,A31)} -> 100 | E31: {=IF(D31=0,"",C31/D31)} -> 0 | F31: {=IF(E31="","",IF(E31<0.4,"Low",IF(E31<0.7,"Moderate","High")))} -> Low | G31: Needs exploration.
A32: Validity & Readiness | B32: Validity | C32: {=_xlfn.SUMIFS('Student_Responses'!$N1:$N537,'Student_Responses'!$E1:$E537,B32,'Student_Responses'!$C1:$C537,A32)} -> 0 | D32: {=_xlfn.SUMIFS('Student_Responses'!$P1:$P537,'Student_Responses'!$E1:$E537,B32,'Student_Responses'!$C1:$C537,A32)} -> 50 | E32: {=IF(D32=0,"",C32/D32)} -> 0 | F32: {=IF(E32="","",IF(E32<0.4,"Low",IF(E32<0.7,"Moderate","High")))} -> Low | G32: Response consistency needs review.

Sheet Dashboard
A1: NeuroPi Dashboard
A2: Key indices for counselor review
A4: Index | B4: Formula Basis | C4: Score | D4: Band | E4: Interpretation
A5: RIASEC Clarity | B5: Top interest concentration | C5: {=MAX('Score_Summary'!E5:E10)} -> 0 | D5: {=IF(C5<0.4,"Low",IF(C5<0.7,"Moderate","High"))} -> Low | E5: Strongest interest signal
A6: Big Five Balance | B6: Adaptive traits average | C6: {=AVERAGE('Score_Summary'!E11:E14,1-'Score_Summary'!E15)} -> 0.2 | D6: {=IF(C6<0.4,"Low",IF(C6<0.7,"Moderate","High"))} -> Low | E6: Behavioral regulation and personality fit
A7: Cognitive Index | B7: Average cognitive score | C7: {=AVERAGE('Score_Summary'!E16:E20)} -> 0 | D7: {=IF(C7<0.4,"Low",IF(C7<0.7,"Moderate","High"))} -> Low | E7: Reasoning capacity
A8: Emotional Sustainability | B8: Confidence/resilience/coping minus stress | C8: {=AVERAGE('Score_Summary'!E22:E24,1-'Score_Summary'!E21)} -> 0.25 | D8: {=IF(C8<0.4,"Low",IF(C8<0.7,"Moderate","High"))} -> Low | E8: Ability to sustain effort
A9: Learning Fit | B9: Dominant learning preference | C9: {=MAX('Score_Summary'!E25:E28)} -> 0 | D9: {=IF(C9<0.4,"Low",IF(C9<0.7,"Moderate","High"))} -> Low | E9: Learning strategy clarity
A10: Career Readiness | B10: Clarity + interest + emotion | C10: {=AVERAGE(C5,C8,'Score_Summary'!E31)} -> 0.083333333 | D10: {=IF(C10<0.4,"Low",IF(C10<0.7,"Moderate","High"))} -> Low | E10: Readiness for decision support
A14: Profile Element | B14: Result
A15: Top RIASEC Code | B15: {=INDEX('Score_Summary'!$B$5:$B$10,MATCH(MAX('Score_Summary'!$E$5:$E$10),'Score_Summary'!$E$5:$E$10,0))} -> R
A16: Top Big Five Trait | B16: {=INDEX('Score_Summary'!$B$11:$B$15,MATCH(MAX('Score_Summary'!$E$11:$E$15),'Score_Summary'!$E$11:$E$15,0))} -> Openness
A17: Dominant Learning Preference | B17: {=INDEX('Score_Summary'!$B$25:$B$28,MATCH(MAX('Score_Summary'!$E$25:$E$28),'Score_Summary'!$E$25:$E$28,0))} -> Visual
A18: Primary Alert | B18: {=IF('Score_Summary'!E21>0.7,"High stress sensitivity",IF('Score_Summary'!E12<0.4,"Low study consistency",IF('Score_Summary'!E31<0.4,"Career confusion","No major alert")))} -> Low study consistency
A19: Counselor Focus | B19: {=IF(B18="High stress sensitivity","Emotional safety and pressure management",IF(B18="Low study consistency","Study routine and accountability",IF(B18="Career confusion","Exploration and stream mapping","Strengths confirmation and growth plan")))} -> Study routine and accountability

Sheet Report_Summary
A1: NeuroPi Student Report Summary
A2: Auto-generated draft language
A4: Student Summary | B4: {=CONCATENATE("This student shows ",'Dashboard'!D7," cognitive readiness, ",'Dashboard'!D8," emotional sustainability, and a dominant ",'Dashboard'!B17," learning preference. The strongest interest code is ",'Dashboard'!B15,".")} -> This student shows Low cognitive readiness, Low emotional sustainability, and a dominant Visual learning preference. The strongest interest code is R.
A5: Interest Interpretation | B5: {=CONCATENATE("The primary RIASEC code is ",'Dashboard'!B15,". Use this as a directional signal for career exploration, not a fixed decision.")} -> The primary RIASEC code is R. Use this as a directional signal for career exploration, not a fixed decision.
A6: Personality Interpretation | B6: {=CONCATENATE("The strongest Big Five trait is ",'Dashboard'!B16,". Interpret this with study habits, confidence and emotional profile.")} -> The strongest Big Five trait is Openness. Interpret this with study habits, confidence and emotional profile.
A7: Learning Recommendation | B7: {=CONCATENATE("Prioritize ",'Dashboard'!B17," methods with structured practice and regular feedback.")} -> Prioritize Visual methods with structured practice and regular feedback.
A8: Risk/Alert | B8: {=CONCATENATE("Primary alert: ",'Dashboard'!B18,". Counselor focus: ",'Dashboard'!B19,".")} -> Primary alert: Low study consistency. Counselor focus: Study routine and accountability.
A9: Parent Guidance | B9: {="Encourage effort, avoid comparison, discuss future options calmly, and use the report as a growth roadmap rather than a label."} -> Encourage effort, avoid comparison, discuss future options calmly, and use the report as a growth roadmap rather than a label.
A10: Ethical Note | B10: {="This report is developmental and non-diagnostic. It should guide discussion, not replace professional evaluation where needed."} -> This report is developmental and non-diagnostic. It should guide discussion, not replace professional evaluation where needed.

Sheet Answer_Key
A1: Answer Key / Scoring Key
A2: Full key linked from the question bank
A4: {='Question_Bank'!A4} -> QID | B4: {='Question_Bank'!C4} -> Domain | C4: {='Question_Bank'!D4} -> Subdomain | D4: {='Question_Bank'!F4} -> Question Type | E4: {='Question_Bank'!L4} -> Correct/Key | F4: {='Question_Bank'!N4} -> Reverse Scored | G4: {=IF(D4="MCQ","Correct=1, Incorrect=0",IF(F4="Yes","Reverse: 6-response","Direct: response score"))} -> Direct: response score
A5: {='Question_Bank'!A5} -> NPI0001 | B5: {='Question_Bank'!C5} -> RIASEC Interest | C5: {='Question_Bank'!D5} -> Realistic | D5: {='Question_Bank'!F5} -> Likert | E5: {='Question_Bank'!L5} -> 0 | F5: {='Question_Bank'!N5} -> No | G5: {=IF(D5="MCQ","Correct=1, Incorrect=0",IF(F5="Yes","Reverse: 6-response","Direct: response score"))} -> Direct: response score
A6: {='Question_Bank'!A6} -> NPI0002 | B6: {='Question_Bank'!C6} -> RIASEC Interest | C6: {='Question_Bank'!D6} -> Realistic | D6: {='Question_Bank'!F6} -> Likert | E6: {='Question_Bank'!L6} -> 0 | F6: {='Question_Bank'!N6} -> No | G6: {=IF(D6="MCQ","Correct=1, Incorrect=0",IF(F6="Yes","Reverse: 6-response","Direct: response score"))} -> Direct: response score
A7: {='Question_Bank'!A7} -> NPI0003 | B7: {='Question_Bank'!C7} -> RIASEC Interest | C7: {='Question_Bank'!D7} -> Realistic | D7: {='Question_Bank'!F7} -> Likert | E7: {='Question_Bank'!L7} -> 0 | F7: {='Question_Bank'!N7} -> No | G7: {=IF(D7="MCQ","Correct=1, Incorrect=0",IF(F7="Yes","Reverse: 6-response","Direct: response score"))} -> Direct: response score
A8: {='Question_Bank'!A8} -> NPI0004 | B8: {='Question_Bank'!C8} -> RIASEC Interest | C8: {='Question_Bank'!D8} -> Realistic | D8: {='Question_Bank'!F8} -> Likert | E8: {='Question_Bank'!L8} -> 0 | F8: {='Question_Bank'!N8} -> No | G8: {=IF(D8="MCQ","Correct=1, Incorrect=0",IF(F8="Yes","Reverse: 6-response","Direct: response score"))} -> Direct: response score
A9: {='Question_Bank'!A9} -> NPI0005 | B9: {='Question_Bank'!C9} -> RIASEC Interest | C9: {='Question_Bank'!D9} -> Realistic | D9: {='Question_Bank'!F9} -> Likert | E9: {='Question_Bank'!L9} -> 0 | F9: {='Question_Bank'!N9} -> No | G9: {=IF(D9="MCQ","Correct=1, Incorrect=0",IF(F9="Yes","Reverse: 6-response","Direct: response score"))} -> Direct: response score
A10: {='Question_Bank'!A10} -> NPI0006 | B10: {='Question_Bank'!C10} -> RIASEC Interest | C10: {='Question_Bank'!D10} -> Realistic | D10: {='Question_Bank'!F10} -> Likert | E10: {='Question_Bank'!L10} -> 0 | F10: {='Question_Bank'!N10} -> No | G10: {=IF(D10="MCQ","Correct=1, Incorrect=0",IF(F10="Yes","Reverse: 6-response","Direct: response score"))} -> Direct: response score
A11: {='Question_Bank'!A11} -> NPI0007 | B11: {='Question_Bank'!C11} -> RIASEC Interest | C11: {='Question_Bank'!D11} -> Realistic | D11: {='Question_Bank'!F11} -> Likert | E11: {='Question_Bank'!L11} -> 0 | F11: {='Question_Bank'!N11} -> No | G11: {=IF(D11="MCQ","Correct=1, Incorrect=0",IF(F11="Yes","Reverse: 6-response","Direct: response score"))} -> Direct: response score
A12: {='Question_Bank'!A12} -> NPI0008 | B12: {='Question_Bank'!C12} -> RIASEC Interest | C12: {='Question_Bank'!D12} -> Realistic | D12: {='Question_Bank'!F12} -> Likert | E12: {='Question_Bank'!L12} -> 0 | F12: {='Question_Bank'!N12} -> No | G12: {=IF(D12="MCQ","Correct=1, Incorrect=0",IF(F12="Yes","Reverse: 6-response","Direct: response score"))} -> Direct: response score
A13: {='Question_Bank'!A13} -> NPI0009 | B13: {='Question_Bank'!C13} -> RIASEC Interest | C13: {='Question_Bank'!D13} -> Realistic | D13: {='Question_Bank'!F13} -> Likert | E13: {='Question_Bank'!L13} -> 0 | F13: {='Question_Bank'!N13} -> No | G13: {=IF(D13="MCQ","Correct=1, Incorrect=0",IF(F13="Yes","Reverse: 6-response","Direct: response score"))} -> Direct: response score
A14: {='Question_Bank'!A14} -> NPI0010 | B14: {='Question_Bank'!C14} -> RIASEC Interest | C14: {='Question_Bank'!D14} -> Realistic | D14: {='Question_Bank'!F14} -> Likert | E14: {='Question_Bank'!L14} -> 0 | F14: {='Question_Bank'!N14} -> No | G14: {=IF(D14="MCQ","Correct=1, Incorrect=0",IF(F14="Yes","Reverse: 6-response","Direct: response score"))} -> Direct: response score
A15: {='Question_Bank'!A15} -> NPI0011 | B15: {='Question_Bank'!C15} -> RIASEC Interest | C15: {='Question_Bank'!D15} -> Realistic | D15: {='Question_Bank'!F15} -> Likert | E15: {='Question_Bank'!L15} -> 0 | F15: {='Question_Bank'!N15} -> No | G15: {=IF(D15="MCQ","Correct=1, Incorrect=0",IF(F15="Yes","Reverse: 6-response","Direct: response score"))} -> Direct: response score
... A529: {='Question_Bank'!A529} -> NPI0525 | B529: {='Question_Bank'!C529} -> Validity & Readiness | C529: {='Question_Bank'!D529} -> Validity | D529: {='Question_Bank'!F529} -> Likert | E529: {='Question_Bank'!L529} -> 0 | F529: {='Question_Bank'!N529} -> No | G529: {=IF(D529="MCQ","Correct=1, Incorrect=0",IF(F529="Yes","Reverse: 6-response","Direct: response score"))} -> Direct: response score

Sheet Administration_Guide
A1: Administration & Interpretation Guide
A2: For NeuroPi counselors and schools
A4: Recommended grade group | B4: Grade 8–12. Use shorter deployment versions for school pilots and full bank for adaptive platform use.
A5: Minimum test set | B5: 36 RIASEC + 40 Big Five + 20 Cognitive + 20 Emotional + 12 Learning/Study items.
A6: Scoring bands | B6: Low <40%, Moderate 40–69%, High ≥70%. Interpret contextually.
A7: RIASEC | B7: Answers: What do you like? Use top 2–3 codes for career cluster exploration.
A8: Big Five | B8: Answers: How do you behave? Use for study routine, collaboration, stress sensitivity and learning environment.
A9: Cognitive | B9: Answers: What can you do? Use as readiness, not fixed ability label.
A10: Emotional | B10: Answers: Will you sustain it? Use for stress, confidence, resilience and coping support.
A11: Counseling caution | B11: Never say “you cannot do this career”. Say “this pathway may require these supports”.
A12: Validity | B12: If validity/readiness is low, use interview follow-up or re-administer shorter form.
A13: Data privacy | B13: Collect consent and restrict access to reports.

Sheet Short_Form_Blueprint
A1: Short Form / Adaptive Test Blueprint
A2: Suggested item counts for deployment
A4: Layer | B4: What it answers | C4: Recommended Items | D4: Use | E4: Notes
A5: RIASEC | B5: What do you like? | C5: 36–60 | D5: Career interest mapping | E5: Balanced across R/I/A/S/E/C
A6: Big Five | B6: How do you behave? | C6: 40–50 | D6: Personality tendency | E6: Include reverse-coded items
A7: Cognitive | B7: What can you do? | C7: 20–30 | D7: Reasoning profile | E7: Use mixed difficulty
A8: Emotional | B8: Will you sustain it? | C8: 20–30 | D8: Stress, confidence, resilience, coping | E8: Use soft language
A9: Learning Style | B9: How do you learn? | C9: 12–20 | D9: Study strategy | E9: Do not label as fixed style
A10: Motivation/Study Habits | B10: What support is needed? | C10: 10–20 | D10: Action planning | E10: Useful for interventions
A11: Validity | B11: Are responses reliable? | C11: 5–10 | D11: Quality check | E11: Internal use
